Workbook

Sheet README & Method
A1: Master Thesis — Threat-Modeling Results
A2: Controlled comparison of two LLMs (two runs each), ThreMoLIA, OWASP Threat Dragon, and Microsoft TMT across three scenarios.
A4: Workbook purpose and operating rules
A5: Purpose | B5: Maintain one auditable master record for raw tool output and separate thesis analysis.
A6: Unit of entry | B6: One row per threat from an LLM run or a tool. Preserve the original title, category, severity and evidence reference.
A7: Comparison rule | B7: Use semantically equivalent architectures and the same threat-model prompt for LLM R1/R2. Record each approach independently.
A8: Analysis rule | B8: Enter raw results only in Scenario 1–3 Raw. All summary sheets are formula-driven and should not be overwritten.
A10: Suggested workflow
A11: 1 | B11: Complete Experiment Metadata: version, model/template, export date, and architecture equivalence notes.
A12: 2 | B12: For each scenario, paste or transcribe every threat from ChatGPT R1/R2, Llama R1/R2, ThreMoLIA, Threat Dragon and TMT into its Raw Results sheet.
A13: 3 | B13: Use the controlled fields: STRIDE, LLM relevance/theme, inclusion decision, cross-approach mapping and DFD element.
A14: 4 | B14: Review All-Approach Comparison and STRIDE Summary after every approach has been recorded for a scenario.
A15: 5 | B15: Use LLM Coverage and Architecture Coverage to support the qualitative comparison.
A16: 6 | B16: Write thesis narrative observations in Cross-Scenario Analysis; formula cells remain traceable to raw records.
A18: Definitions used in this workbook
A19: Raw finding | B19: Unmodified tool-generated threat; retain it even if later excluded from final reporting.
A20: Included | B20: A reviewed finding retained for the formal comparison. This is an analysis decision, not a deletion rule.
A21: Cross-approach mapping | B21: A shared analyst-defined ID used whenever any two approaches describe the same substantive issue.
A22: LLM theme | B22: Use only where a threat directly concerns LLM behavior, data, integration, knowledge base, or LLM access context.
A23: Architecture coverage | B23: Counts included findings mapped to the same named DFD component. Use exact names consistently.

Sheet Experiment Metadata
A1: Experiment Metadata
A2: Complete once per approach/run. The four LLM runs should record the same prompt, architecture and session-control conditions.
A4: Scenario / approach run register
A5: Scenario | B5: Approach | C5: Approach family | D5: Run / session condition | E5: Model / tool version | F5: Prompt / template ID | G5: Modelled architecture version | H5: Date generated | I5: Export / evidence location / method notes
A6: Scenario 1 | B6: ChatGPT R1 | C6: LLM — ChatGPT | D6: Independent run 1
A7: Scenario 1 | B7: ChatGPT R2 | C7: LLM — ChatGPT | D7: Independent run 2
A8: Scenario 1 | B8: Llama R1 | C8: LLM — Llama | D8: Independent run 1
A9: Scenario 1 | B9: Llama R2 | C9: LLM — Llama | D9: Independent run 2
A10: Scenario 1 | B10: ThreMoLIA | C10: LLM-assisted threat-modeling tool | D10: Single tool output
A11: Scenario 1 | B11: OWASP Threat Dragon | C11: Threat-modeling tool | D11: Single tool output
A12: Scenario 1 | B12: Microsoft TMT | C12: Threat-modeling tool | D12: Single tool output
A13: Scenario 2 | B13: ChatGPT R1 | C13: LLM — ChatGPT | D13: Independent run 1
A14: Scenario 2 | B14: ChatGPT R2 | C14: LLM — ChatGPT | D14: Independent run 2
A15: Scenario 2 | B15: Llama R1 | C15: LLM — Llama | D15: Independent run 1
A16: Scenario 2 | B16: Llama R2 | C16: LLM — Llama | D16: Independent run 2
A17: Scenario 2 | B17: ThreMoLIA | C17: LLM-assisted threat-modeling tool | D17: Single tool output
... A26: Scenario 3 | B26: Microsoft TMT | C26: Threat-modeling tool | D26: Single tool output
A29: Scenario architecture register
A30: Scenario | B30: Scenario name / purpose | C30: External entities | D30: Processes | E30: Data stores | F30: Trust boundaries | G30: LLM / external AI dependency | H30: Architecture consistency note | I30: LLM prompt consistency note
A31: Scenario 1 | B31: Authentication Assistant | C31: End User / Browser; External LLM Provider | D31: Web Frontend; Authentication Service; Session Management; AI Chatbot; LLM Integration | E31: User Database; Session Storage; Knowledge Base | F31: Application boundary; external LLM provider boundary | G31: External LLM Provider | H31: Use semantically equivalent DFDs in both tools. | I31: Use same baseline prompt for ChatGPT R1/R2 and Llama R1/R2.
A32: Scenario 2
A33: Scenario 3

Sheet Lists & Codebook
A1: Lists & Coding Codebook
A2: Validation lists and controlled definitions. Edit list values here before entering results if your thesis protocol uses different terms.
A4: Approaches | E4: Coding notes
A5: ChatGPT R1 | E5: Field | F5: Use | G5: Analysis effect | H5: Example
A6: ChatGPT R2 | E6: STRIDE category | F6: Map to one primary STRIDE class for comparative summaries. | G6: Feeds STRIDE Summary. | H6: Information Disclosure
A7: Llama R1 | E7: Final inclusion | F7: Yes if retained in formal results after review. | G7: Filters approach and coverage metrics. | H7: Yes
A8: Llama R2 | E8: Cross-approach mapping ID | F8: Same ID where two or more approaches identify the same substantive threat. | G8: Counts mapped records in comparison tables. | H8: S1-MAP-03
A9: ThreMoLIA | E9: DFD element | F9: Use exact architecture component name. | G9: Feeds Architecture Coverage. | H9: LLM Integration Service
A10: OWASP Threat Dragon | E10: LLM theme | F10: Select only for LLM-relevant finding. | G10: Feeds LLM Coverage. | H10: Prompt injection
A11: Microsoft TMT | E11: Raw evidence reference | F11: Export page, threat ID, or saved screenshot location. | G11: Preserves audit trail. | H11: TMT report p. 4
A13: STRIDE
A14: Spoofing
A15: Tampering
A16: Repudiation
A17: Information Disclosure
A18: Denial of Service
A19: Elevation of Privilege
A21: Component types
A22: External Entity
A23: Process
A24: Data Store
A25: Data Flow
... A55: LLM authorization / context isolation

Sheet Scenario 1 Raw
A1: Scenario 1 — Raw Tool Results
A2: Enter one row per generated threat. Keep the original output intact; use review fields only after the raw result is preserved.
A4: Input area: record ChatGPT R1/R2, Llama R1/R2, ThreMoLIA, OWASP Threat Dragon and Microsoft TMT in the same scenario register. Formulas read rows 6–155. | B4: Input area: record ChatGPT R1/R2, Llama R1/R2, ThreMoLIA, OWASP Threat Dragon and Microsoft TMT in the same scenario register. Formulas read rows 6–155. | C4: Input area: record ChatGPT R1/R2, Llama R1/R2, ThreMoLIA, OWASP Threat Dragon and Microsoft TMT in the same scenario register. Formulas read rows 6–155. | D4: Input area: record ChatGPT R1/R2, Llama R1/R2, ThreMoLIA, OWASP Threat Dragon and Microsoft TMT in the same scenario register. Formulas read rows 6–155. | E4: Input area: record ChatGPT R1/R2, Llama R1/R2, ThreMoLIA, OWASP Threat Dragon and Microsoft TMT in the same scenario register. Formulas read rows 6–155. | F4: Input area: record ChatGPT R1/R2, Llama R1/R2, ThreMoLIA, OWASP Threat Dragon and Microsoft TMT in the same scenario register. Formulas read rows 6–155. | G4: Input area: record ChatGPT R1/R2, Llama R1/R2, ThreMoLIA, OWASP Threat Dragon and Microsoft TMT in the same scenario register. Formulas read rows 6–155. | H4: Input area: record ChatGPT R1/R2, Llama R1/R2, ThreMoLIA, OWASP Threat Dragon and Microsoft TMT in the same scenario register. Formulas read rows 6–155. | I4: Input area: record ChatGPT R1/R2, Llama R1/R2, ThreMoLIA, OWASP Threat Dragon and Microsoft TMT in the same scenario register. Formulas read rows 6–155. | J4: Input area: record ChatGPT R1/R2, Llama R1/R2, ThreMoLIA, OWASP Threat Dragon and Microsoft TMT in the same scenario register. Formulas read rows 6–155. | K4: Input area: record ChatGPT R1/R2, Llama R1/R2, ThreMoLIA, OWASP Threat Dragon and Microsoft TMT in the same scenario register. Formulas read rows 6–155. | L4: Input area: record ChatGPT R1/R2, Llama R1/R2, ThreMoLIA, OWASP Threat Dragon and Microsoft TMT in the same scenario register. Formulas read rows 6–155. | M4: Input area: record ChatGPT R1/R2, Llama R1/R2, ThreMoLIA, OWASP Threat Dragon and Microsoft TMT in the same scenario register. Formulas read rows 6–155. | N4: Input area: record ChatGPT R1/R2, Llama R1/R2, ThreMoLIA, OWASP Threat Dragon and Microsoft TMT in the same scenario register. Formulas read rows 6–155. | O4: Input area: record ChatGPT R1/R2, Llama R1/R2, ThreMoLIA, OWASP Threat Dragon and Microsoft TMT in the same scenario register. Formulas read rows 6–155. | P4: Input area: record ChatGPT R1/R2, Llama R1/R2, ThreMoLIA, OWASP Threat Dragon and Microsoft TMT in the same scenario register. Formulas read rows 6–155. | Q4: Input area: record ChatGPT R1/R2, Llama R1/R2, ThreMoLIA, OWASP Threat Dragon and Microsoft TMT in the same scenario register. Formulas read rows 6–155. | R4: Input area: record ChatGPT R1/R2, Llama R1/R2, ThreMoLIA, OWASP Threat Dragon and Microsoft TMT in the same scenario register. Formulas read rows 6–155. | S4: Input area: record ChatGPT R1/R2, Llama R1/R2, ThreMoLIA, OWASP Threat Dragon and Microsoft TMT in the same scenario register. Formulas read rows 6–155.
A5: Record ID | B5: Approach / run | C5: Output ID | D5: Threat title (raw) | E5: Threat description / property (raw) | F5: DFD element / component | G5: Component type | H5: Data flow / interaction | I5: Trust boundary | J5: Source category (raw) | K5: STRIDE category | L5: Severity (raw) | M5: LLM-relevant? | N5: LLM theme | O5: Raw evidence reference | P5: Review status | Q5: Final inclusion? | R5: Cross-approach mapping ID | S5: Analyst notes

Sheet Scenario 2 Raw
A1: Scenario 2 — Raw Tool Results
A2: Enter one row per generated threat. Keep the original output intact; use review fields only after the raw result is preserved.
A4: Input area: record ChatGPT R1/R2, Llama R1/R2, ThreMoLIA, OWASP Threat Dragon and Microsoft TMT in the same scenario register. Formulas read rows 6–155. | B4: Input area: record ChatGPT R1/R2, Llama R1/R2, ThreMoLIA, OWASP Threat Dragon and Microsoft TMT in the same scenario register. Formulas read rows 6–155. | C4: Input area: record ChatGPT R1/R2, Llama R1/R2, ThreMoLIA, OWASP Threat Dragon and Microsoft TMT in the same scenario register. Formulas read rows 6–155. | D4: Input area: record ChatGPT R1/R2, Llama R1/R2, ThreMoLIA, OWASP Threat Dragon and Microsoft TMT in the same scenario register. Formulas read rows 6–155. | E4: Input area: record ChatGPT R1/R2, Llama R1/R2, ThreMoLIA, OWASP Threat Dragon and Microsoft TMT in the same scenario register. Formulas read rows 6–155. | F4: Input area: record ChatGPT R1/R2, Llama R1/R2, ThreMoLIA, OWASP Threat Dragon and Microsoft TMT in the same scenario register. Formulas read rows 6–155. | G4: Input area: record ChatGPT R1/R2, Llama R1/R2, ThreMoLIA, OWASP Threat Dragon and Microsoft TMT in the same scenario register. Formulas read rows 6–155. | H4: Input area: record ChatGPT R1/R2, Llama R1/R2, ThreMoLIA, OWASP Threat Dragon and Microsoft TMT in the same scenario register. Formulas read rows 6–155. | I4: Input area: record ChatGPT R1/R2, Llama R1/R2, ThreMoLIA, OWASP Threat Dragon and Microsoft TMT in the same scenario register. Formulas read rows 6–155. | J4: Input area: record ChatGPT R1/R2, Llama R1/R2, ThreMoLIA, OWASP Threat Dragon and Microsoft TMT in the same scenario register. Formulas read rows 6–155. | K4: Input area: record ChatGPT R1/R2, Llama R1/R2, ThreMoLIA, OWASP Threat Dragon and Microsoft TMT in the same scenario register. Formulas read rows 6–155. | L4: Input area: record ChatGPT R1/R2, Llama R1/R2, ThreMoLIA, OWASP Threat Dragon and Microsoft TMT in the same scenario register. Formulas read rows 6–155. | M4: Input area: record ChatGPT R1/R2, Llama R1/R2, ThreMoLIA, OWASP Threat Dragon and Microsoft TMT in the same scenario register. Formulas read rows 6–155. | N4: Input area: record ChatGPT R1/R2, Llama R1/R2, ThreMoLIA, OWASP Threat Dragon and Microsoft TMT in the same scenario register. Formulas read rows 6–155. | O4: Input area: record ChatGPT R1/R2, Llama R1/R2, ThreMoLIA, OWASP Threat Dragon and Microsoft TMT in the same scenario register. Formulas read rows 6–155. | P4: Input area: record ChatGPT R1/R2, Llama R1/R2, ThreMoLIA, OWASP Threat Dragon and Microsoft TMT in the same scenario register. Formulas read rows 6–155. | Q4: Input area: record ChatGPT R1/R2, Llama R1/R2, ThreMoLIA, OWASP Threat Dragon and Microsoft TMT in the same scenario register. Formulas read rows 6–155. | R4: Input area: record ChatGPT R1/R2, Llama R1/R2, ThreMoLIA, OWASP Threat Dragon and Microsoft TMT in the same scenario register. Formulas read rows 6–155. | S4: Input area: record ChatGPT R1/R2, Llama R1/R2, ThreMoLIA, OWASP Threat Dragon and Microsoft TMT in the same scenario register. Formulas read rows 6–155.
A5: Record ID | B5: Approach / run | C5: Output ID | D5: Threat title (raw) | E5: Threat description / property (raw) | F5: DFD element / component | G5: Component type | H5: Data flow / interaction | I5: Trust boundary | J5: Source category (raw) | K5: STRIDE category | L5: Severity (raw) | M5: LLM-relevant? | N5: LLM theme | O5: Raw evidence reference | P5: Review status | Q5: Final inclusion? | R5: Cross-approach mapping ID | S5: Analyst notes

Sheet Scenario 3 Raw
A1: Scenario 3 — Raw Tool Results
A2: Enter one row per generated threat. Keep the original output intact; use review fields only after the raw result is preserved.
A4: Input area: record ChatGPT R1/R2, Llama R1/R2, ThreMoLIA, OWASP Threat Dragon and Microsoft TMT in the same scenario register. Formulas read rows 6–155. | B4: Input area: record ChatGPT R1/R2, Llama R1/R2, ThreMoLIA, OWASP Threat Dragon and Microsoft TMT in the same scenario register. Formulas read rows 6–155. | C4: Input area: record ChatGPT R1/R2, Llama R1/R2, ThreMoLIA, OWASP Threat Dragon and Microsoft TMT in the same scenario register. Formulas read rows 6–155. | D4: Input area: record ChatGPT R1/R2, Llama R1/R2, ThreMoLIA, OWASP Threat Dragon and Microsoft TMT in the same scenario register. Formulas read rows 6–155. | E4: Input area: record ChatGPT R1/R2, Llama R1/R2, ThreMoLIA, OWASP Threat Dragon and Microsoft TMT in the same scenario register. Formulas read rows 6–155. | F4: Input area: record ChatGPT R1/R2, Llama R1/R2, ThreMoLIA, OWASP Threat Dragon and Microsoft TMT in the same scenario register. Formulas read rows 6–155. | G4: Input area: record ChatGPT R1/R2, Llama R1/R2, ThreMoLIA, OWASP Threat Dragon and Microsoft TMT in the same scenario register. Formulas read rows 6–155. | H4: Input area: record ChatGPT R1/R2, Llama R1/R2, ThreMoLIA, OWASP Threat Dragon and Microsoft TMT in the same scenario register. Formulas read rows 6–155. | I4: Input area: record ChatGPT R1/R2, Llama R1/R2, ThreMoLIA, OWASP Threat Dragon and Microsoft TMT in the same scenario register. Formulas read rows 6–155. | J4: Input area: record ChatGPT R1/R2, Llama R1/R2, ThreMoLIA, OWASP Threat Dragon and Microsoft TMT in the same scenario register. Formulas read rows 6–155. | K4: Input area: record ChatGPT R1/R2, Llama R1/R2, ThreMoLIA, OWASP Threat Dragon and Microsoft TMT in the same scenario register. Formulas read rows 6–155. | L4: Input area: record ChatGPT R1/R2, Llama R1/R2, ThreMoLIA, OWASP Threat Dragon and Microsoft TMT in the same scenario register. Formulas read rows 6–155. | M4: Input area: record ChatGPT R1/R2, Llama R1/R2, ThreMoLIA, OWASP Threat Dragon and Microsoft TMT in the same scenario register. Formulas read rows 6–155. | N4: Input area: record ChatGPT R1/R2, Llama R1/R2, ThreMoLIA, OWASP Threat Dragon and Microsoft TMT in the same scenario register. Formulas read rows 6–155. | O4: Input area: record ChatGPT R1/R2, Llama R1/R2, ThreMoLIA, OWASP Threat Dragon and Microsoft TMT in the same scenario register. Formulas read rows 6–155. | P4: Input area: record ChatGPT R1/R2, Llama R1/R2, ThreMoLIA, OWASP Threat Dragon and Microsoft TMT in the same scenario register. Formulas read rows 6–155. | Q4: Input area: record ChatGPT R1/R2, Llama R1/R2, ThreMoLIA, OWASP Threat Dragon and Microsoft TMT in the same scenario register. Formulas read rows 6–155. | R4: Input area: record ChatGPT R1/R2, Llama R1/R2, ThreMoLIA, OWASP Threat Dragon and Microsoft TMT in the same scenario register. Formulas read rows 6–155. | S4: Input area: record ChatGPT R1/R2, Llama R1/R2, ThreMoLIA, OWASP Threat Dragon and Microsoft TMT in the same scenario register. Formulas read rows 6–155.
A5: Record ID | B5: Approach / run | C5: Output ID | D5: Threat title (raw) | E5: Threat description / property (raw) | F5: DFD element / component | G5: Component type | H5: Data flow / interaction | I5: Trust boundary | J5: Source category (raw) | K5: STRIDE category | L5: Severity (raw) | M5: LLM-relevant? | N5: LLM theme | O5: Raw evidence reference | P5: Review status | Q5: Final inclusion? | R5: Cross-approach mapping ID | S5: Analyst notes

Sheet All Approaches
A1: All-Approach Comparison
A2: Formula-driven comparison of ChatGPT R1/R2, Llama R1/R2, ThreMoLIA, OWASP Threat Dragon and Microsoft TMT.
A4: Scenario | B4: Approach | C4: Approach family | D4: Raw findings | E4: Reviewed | F4: Included | G4: Excluded / out of scope | H4: Duplicates / noise | I4: Mapped to another approach | J4: Included / raw | K4: Mapped / included | L4: Comparative observation (manual)
A5: Scenario 1 | B5: ChatGPT R1 | C5: LLM — ChatGPT | D5: =COUNTIFS('Scenario 1 Raw'!$B$6:$B$155,$B5,'Scenario 1 Raw'!$C$6:$C$155,"<>") -> 0 | E5: =COUNTIFS('Scenario 1 Raw'!$B$6:$B$155,$B5,'Scenario 1 Raw'!$C$6:$C$155,"<>",'Scenario 1 Raw'!$P$6:$P$155,"Reviewed") -> 0 | F5: =COUNTIFS('Scenario 1 Raw'!$B$6:$B$155,$B5,'Scenario 1 Raw'!$C$6:$C$155,"<>",'Scenario 1 Raw'!$Q$6:$Q$155,"Yes") -> 0 | G5: =COUNTIFS('Scenario 1 Raw'!$B$6:$B$155,$B5,'Scenario 1 Raw'!$C$6:$C$155,"<>",'Scenario 1 Raw'!$P$6:$P$155,"Excluded")+COUNTIFS('Scenario 1 Raw'!$B$6:$B$155,$B5,'Scenario 1 Raw'!$C$6:$C$155,"<>",'Scenario 1 Raw'!$P$6:$P$155,"Out of scope") -> 0 | H5: =COUNTIFS('Scenario 1 Raw'!$B$6:$B$155,$B5,'Scenario 1 Raw'!$C$6:$C$155,"<>",'Scenario 1 Raw'!$P$6:$P$155,"Duplicate / noise") -> 0 | I5: =COUNTIFS('Scenario 1 Raw'!$B$6:$B$155,$B5,'Scenario 1 Raw'!$C$6:$C$155,"<>",'Scenario 1 Raw'!$Q$6:$Q$155,"Yes",'Scenario 1 Raw'!$R$6:$R$155,"<>") -> 0 | J5: =IFERROR(F5/D5,0) -> 0 | K5: =IFERROR(I5/F5,0) -> 0
A6: Scenario 1 | B6: ChatGPT R2 | C6: LLM — ChatGPT | D6: =COUNTIFS('Scenario 1 Raw'!$B$6:$B$155,$B6,'Scenario 1 Raw'!$C$6:$C$155,"<>") -> 0 | E6: =COUNTIFS('Scenario 1 Raw'!$B$6:$B$155,$B6,'Scenario 1 Raw'!$C$6:$C$155,"<>",'Scenario 1 Raw'!$P$6:$P$155,"Reviewed") -> 0 | F6: =COUNTIFS('Scenario 1 Raw'!$B$6:$B$155,$B6,'Scenario 1 Raw'!$C$6:$C$155,"<>",'Scenario 1 Raw'!$Q$6:$Q$155,"Yes") -> 0 | G6: =COUNTIFS('Scenario 1 Raw'!$B$6:$B$155,$B6,'Scenario 1 Raw'!$C$6:$C$155,"<>",'Scenario 1 Raw'!$P$6:$P$155,"Excluded")+COUNTIFS('Scenario 1 Raw'!$B$6:$B$155,$B6,'Scenario 1 Raw'!$C$6:$C$155,"<>",'Scenario 1 Raw'!$P$6:$P$155,"Out of scope") -> 0 | H6: =COUNTIFS('Scenario 1 Raw'!$B$6:$B$155,$B6,'Scenario 1 Raw'!$C$6:$C$155,"<>",'Scenario 1 Raw'!$P$6:$P$155,"Duplicate / noise") -> 0 | I6: =COUNTIFS('Scenario 1 Raw'!$B$6:$B$155,$B6,'Scenario 1 Raw'!$C$6:$C$155,"<>",'Scenario 1 Raw'!$Q$6:$Q$155,"Yes",'Scenario 1 Raw'!$R$6:$R$155,"<>") -> 0 | J6: =IFERROR(F6/D6,0) -> 0 | K6: =IFERROR(I6/F6,0) -> 0
A7: Scenario 1 | B7: Llama R1 | C7: LLM — Llama | D7: =COUNTIFS('Scenario 1 Raw'!$B$6:$B$155,$B7,'Scenario 1 Raw'!$C$6:$C$155,"<>") -> 0 | E7: =COUNTIFS('Scenario 1 Raw'!$B$6:$B$155,$B7,'Scenario 1 Raw'!$C$6:$C$155,"<>",'Scenario 1 Raw'!$P$6:$P$155,"Reviewed") -> 0 | F7: =COUNTIFS('Scenario 1 Raw'!$B$6:$B$155,$B7,'Scenario 1 Raw'!$C$6:$C$155,"<>",'Scenario 1 Raw'!$Q$6:$Q$155,"Yes") -> 0 | G7: =COUNTIFS('Scenario 1 Raw'!$B$6:$B$155,$B7,'Scenario 1 Raw'!$C$6:$C$155,"<>",'Scenario 1 Raw'!$P$6:$P$155,"Excluded")+COUNTIFS('Scenario 1 Raw'!$B$6:$B$155,$B7,'Scenario 1 Raw'!$C$6:$C$155,"<>",'Scenario 1 Raw'!$P$6:$P$155,"Out of scope") -> 0 | H7: =COUNTIFS('Scenario 1 Raw'!$B$6:$B$155,$B7,'Scenario 1 Raw'!$C$6:$C$155,"<>",'Scenario 1 Raw'!$P$6:$P$155,"Duplicate / noise") -> 0 | I7: =COUNTIFS('Scenario 1 Raw'!$B$6:$B$155,$B7,'Scenario 1 Raw'!$C$6:$C$155,"<>",'Scenario 1 Raw'!$Q$6:$Q$155,"Yes",'Scenario 1 Raw'!$R$6:$R$155,"<>") -> 0 | J7: =IFERROR(F7/D7,0) -> 0 | K7: =IFERROR(I7/F7,0) -> 0
A8: Scenario 1 | B8: Llama R2 | C8: LLM — Llama | D8: =COUNTIFS('Scenario 1 Raw'!$B$6:$B$155,$B8,'Scenario 1 Raw'!$C$6:$C$155,"<>") -> 0 | E8: =COUNTIFS('Scenario 1 Raw'!$B$6:$B$155,$B8,'Scenario 1 Raw'!$C$6:$C$155,"<>",'Scenario 1 Raw'!$P$6:$P$155,"Reviewed") -> 0 | F8: =COUNTIFS('Scenario 1 Raw'!$B$6:$B$155,$B8,'Scenario 1 Raw'!$C$6:$C$155,"<>",'Scenario 1 Raw'!$Q$6:$Q$155,"Yes") -> 0 | G8: =COUNTIFS('Scenario 1 Raw'!$B$6:$B$155,$B8,'Scenario 1 Raw'!$C$6:$C$155,"<>",'Scenario 1 Raw'!$P$6:$P$155,"Excluded")+COUNTIFS('Scenario 1 Raw'!$B$6:$B$155,$B8,'Scenario 1 Raw'!$C$6:$C$155,"<>",'Scenario 1 Raw'!$P$6:$P$155,"Out of scope") -> 0 | H8: =COUNTIFS('Scenario 1 Raw'!$B$6:$B$155,$B8,'Scenario 1 Raw'!$C$6:$C$155,"<>",'Scenario 1 Raw'!$P$6:$P$155,"Duplicate / noise") -> 0 | I8: =COUNTIFS('Scenario 1 Raw'!$B$6:$B$155,$B8,'Scenario 1 Raw'!$C$6:$C$155,"<>",'Scenario 1 Raw'!$Q$6:$Q$155,"Yes",'Scenario 1 Raw'!$R$6:$R$155,"<>") -> 0 | J8: =IFERROR(F8/D8,0) -> 0 | K8: =IFERROR(I8/F8,0) -> 0
A9: Scenario 1 | B9: ThreMoLIA | C9: LLM-assisted threat-modeling tool | D9: =COUNTIFS('Scenario 1 Raw'!$B$6:$B$155,$B9,'Scenario 1 Raw'!$C$6:$C$155,"<>") -> 0 | E9: =COUNTIFS('Scenario 1 Raw'!$B$6:$B$155,$B9,'Scenario 1 Raw'!$C$6:$C$155,"<>",'Scenario 1 Raw'!$P$6:$P$155,"Reviewed") -> 0 | F9: =COUNTIFS('Scenario 1 Raw'!$B$6:$B$155,$B9,'Scenario 1 Raw'!$C$6:$C$155,"<>",'Scenario 1 Raw'!$Q$6:$Q$155,"Yes") -> 0 | G9: =COUNTIFS('Scenario 1 Raw'!$B$6:$B$155,$B9,'Scenario 1 Raw'!$C$6:$C$155,"<>",'Scenario 1 Raw'!$P$6:$P$155,"Excluded")+COUNTIFS('Scenario 1 Raw'!$B$6:$B$155,$B9,'Scenario 1 Raw'!$C$6:$C$155,"<>",'Scenario 1 Raw'!$P$6:$P$155,"Out of scope") -> 0 | H9: =COUNTIFS('Scenario 1 Raw'!$B$6:$B$155,$B9,'Scenario 1 Raw'!$C$6:$C$155,"<>",'Scenario 1 Raw'!$P$6:$P$155,"Duplicate / noise") -> 0 | I9: =COUNTIFS('Scenario 1 Raw'!$B$6:$B$155,$B9,'Scenario 1 Raw'!$C$6:$C$155,"<>",'Scenario 1 Raw'!$Q$6:$Q$155,"Yes",'Scenario 1 Raw'!$R$6:$R$155,"<>") -> 0 | J9: =IFERROR(F9/D9,0) -> 0 | K9: =IFERROR(I9/F9,0) -> 0
A10: Scenario 1 | B10: OWASP Threat Dragon | C10: Threat-modeling tool | D10: =COUNTIFS('Scenario 1 Raw'!$B$6:$B$155,$B10,'Scenario 1 Raw'!$C$6:$C$155,"<>") -> 0 | E10: =COUNTIFS('Scenario 1 Raw'!$B$6:$B$155,$B10,'Scenario 1 Raw'!$C$6:$C$155,"<>",'Scenario 1 Raw'!$P$6:$P$155,"Reviewed") -> 0 | F10: =COUNTIFS('Scenario 1 Raw'!$B$6:$B$155,$B10,'Scenario 1 Raw'!$C$6:$C$155,"<>",'Scenario 1 Raw'!$Q$6:$Q$155,"Yes") -> 0 | G10: =COUNTIFS('Scenario 1 Raw'!$B$6:$B$155,$B10,'Scenario 1 Raw'!$C$6:$C$155,"<>",'Scenario 1 Raw'!$P$6:$P$155,"Excluded")+COUNTIFS('Scenario 1 Raw'!$B$6:$B$155,$B10,'Scenario 1 Raw'!$C$6:$C$155,"<>",'Scenario 1 Raw'!$P$6:$P$155,"Out of scope") -> 0 | H10: =COUNTIFS('Scenario 1 Raw'!$B$6:$B$155,$B10,'Scenario 1 Raw'!$C$6:$C$155,"<>",'Scenario 1 Raw'!$P$6:$P$155,"Duplicate / noise") -> 0 | I10: =COUNTIFS('Scenario 1 Raw'!$B$6:$B$155,$B10,'Scenario 1 Raw'!$C$6:$C$155,"<>",'Scenario 1 Raw'!$Q$6:$Q$155,"Yes",'Scenario 1 Raw'!$R$6:$R$155,"<>") -> 0 | J10: =IFERROR(F10/D10,0) -> 0 | K10: =IFERROR(I10/F10,0) -> 0
A11: Scenario 1 | B11: Microsoft TMT | C11: Threat-modeling tool | D11: =COUNTIFS('Scenario 1 Raw'!$B$6:$B$155,$B11,'Scenario 1 Raw'!$C$6:$C$155,"<>") -> 0 | E11: =COUNTIFS('Scenario 1 Raw'!$B$6:$B$155,$B11,'Scenario 1 Raw'!$C$6:$C$155,"<>",'Scenario 1 Raw'!$P$6:$P$155,"Reviewed") -> 0 | F11: =COUNTIFS('Scenario 1 Raw'!$B$6:$B$155,$B11,'Scenario 1 Raw'!$C$6:$C$155,"<>",'Scenario 1 Raw'!$Q$6:$Q$155,"Yes") -> 0 | G11: =COUNTIFS('Scenario 1 Raw'!$B$6:$B$155,$B11,'Scenario 1 Raw'!$C$6:$C$155,"<>",'Scenario 1 Raw'!$P$6:$P$155,"Excluded")+COUNTIFS('Scenario 1 Raw'!$B$6:$B$155,$B11,'Scenario 1 Raw'!$C$6:$C$155,"<>",'Scenario 1 Raw'!$P$6:$P$155,"Out of scope") -> 0 | H11: =COUNTIFS('Scenario 1 Raw'!$B$6:$B$155,$B11,'Scenario 1 Raw'!$C$6:$C$155,"<>",'Scenario 1 Raw'!$P$6:$P$155,"Duplicate / noise") -> 0 | I11: =COUNTIFS('Scenario 1 Raw'!$B$6:$B$155,$B11,'Scenario 1 Raw'!$C$6:$C$155,"<>",'Scenario 1 Raw'!$Q$6:$Q$155,"Yes",'Scenario 1 Raw'!$R$6:$R$155,"<>") -> 0 | J11: =IFERROR(F11/D11,0) -> 0 | K11: =IFERROR(I11/F11,0) -> 0
A12: Scenario 2 | B12: ChatGPT R1 | C12: LLM — ChatGPT | D12: =COUNTIFS('Scenario 2 Raw'!$B$6:$B$155,$B12,'Scenario 2 Raw'!$C$6:$C$155,"<>") -> 0 | E12: =COUNTIFS('Scenario 2 Raw'!$B$6:$B$155,$B12,'Scenario 2 Raw'!$C$6:$C$155,"<>",'Scenario 2 Raw'!$P$6:$P$155,"Reviewed") -> 0 | F12: =COUNTIFS('Scenario 2 Raw'!$B$6:$B$155,$B12,'Scenario 2 Raw'!$C$6:$C$155,"<>",'Scenario 2 Raw'!$Q$6:$Q$155,"Yes") -> 0 | G12: =COUNTIFS('Scenario 2 Raw'!$B$6:$B$155,$B12,'Scenario 2 Raw'!$C$6:$C$155,"<>",'Scenario 2 Raw'!$P$6:$P$155,"Excluded")+COUNTIFS('Scenario 2 Raw'!$B$6:$B$155,$B12,'Scenario 2 Raw'!$C$6:$C$155,"<>",'Scenario 2 Raw'!$P$6:$P$155,"Out of scope") -> 0 | H12: =COUNTIFS('Scenario 2 Raw'!$B$6:$B$155,$B12,'Scenario 2 Raw'!$C$6:$C$155,"<>",'Scenario 2 Raw'!$P$6:$P$155,"Duplicate / noise") -> 0 | I12: =COUNTIFS('Scenario 2 Raw'!$B$6:$B$155,$B12,'Scenario 2 Raw'!$C$6:$C$155,"<>",'Scenario 2 Raw'!$Q$6:$Q$155,"Yes",'Scenario 2 Raw'!$R$6:$R$155,"<>") -> 0 | J12: =IFERROR(F12/D12,0) -> 0 | K12: =IFERROR(I12/F12,0) -> 0
A13: Scenario 2 | B13: ChatGPT R2 | C13: LLM — ChatGPT | D13: =COUNTIFS('Scenario 2 Raw'!$B$6:$B$155,$B13,'Scenario 2 Raw'!$C$6:$C$155,"<>") -> 0 | E13: =COUNTIFS('Scenario 2 Raw'!$B$6:$B$155,$B13,'Scenario 2 Raw'!$C$6:$C$155,"<>",'Scenario 2 Raw'!$P$6:$P$155,"Reviewed") -> 0 | F13: =COUNTIFS('Scenario 2 Raw'!$B$6:$B$155,$B13,'Scenario 2 Raw'!$C$6:$C$155,"<>",'Scenario 2 Raw'!$Q$6:$Q$155,"Yes") -> 0 | G13: =COUNTIFS('Scenario 2 Raw'!$B$6:$B$155,$B13,'Scenario 2 Raw'!$C$6:$C$155,"<>",'Scenario 2 Raw'!$P$6:$P$155,"Excluded")+COUNTIFS('Scenario 2 Raw'!$B$6:$B$155,$B13,'Scenario 2 Raw'!$C$6:$C$155,"<>",'Scenario 2 Raw'!$P$6:$P$155,"Out of scope") -> 0 | H13: =COUNTIFS('Scenario 2 Raw'!$B$6:$B$155,$B13,'Scenario 2 Raw'!$C$6:$C$155,"<>",'Scenario 2 Raw'!$P$6:$P$155,"Duplicate / noise") -> 0 | I13: =COUNTIFS('Scenario 2 Raw'!$B$6:$B$155,$B13,'Scenario 2 Raw'!$C$6:$C$155,"<>",'Scenario 2 Raw'!$Q$6:$Q$155,"Yes",'Scenario 2 Raw'!$R$6:$R$155,"<>") -> 0 | J13: =IFERROR(F13/D13,0) -> 0 | K13: =IFERROR(I13/F13,0) -> 0
A14: Scenario 2 | B14: Llama R1 | C14: LLM — Llama | D14: =COUNTIFS('Scenario 2 Raw'!$B$6:$B$155,$B14,'Scenario 2 Raw'!$C$6:$C$155,"<>") -> 0 | E14: =COUNTIFS('Scenario 2 Raw'!$B$6:$B$155,$B14,'Scenario 2 Raw'!$C$6:$C$155,"<>",'Scenario 2 Raw'!$P$6:$P$155,"Reviewed") -> 0 | F14: =COUNTIFS('Scenario 2 Raw'!$B$6:$B$155,$B14,'Scenario 2 Raw'!$C$6:$C$155,"<>",'Scenario 2 Raw'!$Q$6:$Q$155,"Yes") -> 0 | G14: =COUNTIFS('Scenario 2 Raw'!$B$6:$B$155,$B14,'Scenario 2 Raw'!$C$6:$C$155,"<>",'Scenario 2 Raw'!$P$6:$P$155,"Excluded")+COUNTIFS('Scenario 2 Raw'!$B$6:$B$155,$B14,'Scenario 2 Raw'!$C$6:$C$155,"<>",'Scenario 2 Raw'!$P$6:$P$155,"Out of scope") -> 0 | H14: =COUNTIFS('Scenario 2 Raw'!$B$6:$B$155,$B14,'Scenario 2 Raw'!$C$6:$C$155,"<>",'Scenario 2 Raw'!$P$6:$P$155,"Duplicate / noise") -> 0 | I14: =COUNTIFS('Scenario 2 Raw'!$B$6:$B$155,$B14,'Scenario 2 Raw'!$C$6:$C$155,"<>",'Scenario 2 Raw'!$Q$6:$Q$155,"Yes",'Scenario 2 Raw'!$R$6:$R$155,"<>") -> 0 | J14: =IFERROR(F14/D14,0) -> 0 | K14: =IFERROR(I14/F14,0) -> 0
A15: Scenario 2 | B15: Llama R2 | C15: LLM — Llama | D15: =COUNTIFS('Scenario 2 Raw'!$B$6:$B$155,$B15,'Scenario 2 Raw'!$C$6:$C$155,"<>") -> 0 | E15: =COUNTIFS('Scenario 2 Raw'!$B$6:$B$155,$B15,'Scenario 2 Raw'!$C$6:$C$155,"<>",'Scenario 2 Raw'!$P$6:$P$155,"Reviewed") -> 0 | F15: =COUNTIFS('Scenario 2 Raw'!$B$6:$B$155,$B15,'Scenario 2 Raw'!$C$6:$C$155,"<>",'Scenario 2 Raw'!$Q$6:$Q$155,"Yes") -> 0 | G15: =COUNTIFS('Scenario 2 Raw'!$B$6:$B$155,$B15,'Scenario 2 Raw'!$C$6:$C$155,"<>",'Scenario 2 Raw'!$P$6:$P$155,"Excluded")+COUNTIFS('Scenario 2 Raw'!$B$6:$B$155,$B15,'Scenario 2 Raw'!$C$6:$C$155,"<>",'Scenario 2 Raw'!$P$6:$P$155,"Out of scope") -> 0 | H15: =COUNTIFS('Scenario 2 Raw'!$B$6:$B$155,$B15,'Scenario 2 Raw'!$C$6:$C$155,"<>",'Scenario 2 Raw'!$P$6:$P$155,"Duplicate / noise") -> 0 | I15: =COUNTIFS('Scenario 2 Raw'!$B$6:$B$155,$B15,'Scenario 2 Raw'!$C$6:$C$155,"<>",'Scenario 2 Raw'!$Q$6:$Q$155,"Yes",'Scenario 2 Raw'!$R$6:$R$155,"<>") -> 0 | J15: =IFERROR(F15/D15,0) -> 0 | K15: =IFERROR(I15/F15,0) -> 0
A16: Scenario 2 | B16: ThreMoLIA | C16: LLM-assisted threat-modeling tool | D16: =COUNTIFS('Scenario 2 Raw'!$B$6:$B$155,$B16,'Scenario 2 Raw'!$C$6:$C$155,"<>") -> 0 | E16: =COUNTIFS('Scenario 2 Raw'!$B$6:$B$155,$B16,'Scenario 2 Raw'!$C$6:$C$155,"<>",'Scenario 2 Raw'!$P$6:$P$155,"Reviewed") -> 0 | F16: =COUNTIFS('Scenario 2 Raw'!$B$6:$B$155,$B16,'Scenario 2 Raw'!$C$6:$C$155,"<>",'Scenario 2 Raw'!$Q$6:$Q$155,"Yes") -> 0 | G16: =COUNTIFS('Scenario 2 Raw'!$B$6:$B$155,$B16,'Scenario 2 Raw'!$C$6:$C$155,"<>",'Scenario 2 Raw'!$P$6:$P$155,"Excluded")+COUNTIFS('Scenario 2 Raw'!$B$6:$B$155,$B16,'Scenario 2 Raw'!$C$6:$C$155,"<>",'Scenario 2 Raw'!$P$6:$P$155,"Out of scope") -> 0 | H16: =COUNTIFS('Scenario 2 Raw'!$B$6:$B$155,$B16,'Scenario 2 Raw'!$C$6:$C$155,"<>",'Scenario 2 Raw'!$P$6:$P$155,"Duplicate / noise") -> 0 | I16: =COUNTIFS('Scenario 2 Raw'!$B$6:$B$155,$B16,'Scenario 2 Raw'!$C$6:$C$155,"<>",'Scenario 2 Raw'!$Q$6:$Q$155,"Yes",'Scenario 2 Raw'!$R$6:$R$155,"<>") -> 0 | J16: =IFERROR(F16/D16,0) -> 0 | K16: =IFERROR(I16/F16,0) -> 0
A17: Scenario 2 | B17: OWASP Threat Dragon | C17: Threat-modeling tool | D17: =COUNTIFS('Scenario 2 Raw'!$B$6:$B$155,$B17,'Scenario 2 Raw'!$C$6:$C$155,"<>") -> 0 | E17: =COUNTIFS('Scenario 2 Raw'!$B$6:$B$155,$B17,'Scenario 2 Raw'!$C$6:$C$155,"<>",'Scenario 2 Raw'!$P$6:$P$155,"Reviewed") -> 0 | F17: =COUNTIFS('Scenario 2 Raw'!$B$6:$B$155,$B17,'Scenario 2 Raw'!$C$6:$C$155,"<>",'Scenario 2 Raw'!$Q$6:$Q$155,"Yes") -> 0 | G17: =COUNTIFS('Scenario 2 Raw'!$B$6:$B$155,$B17,'Scenario 2 Raw'!$C$6:$C$155,"<>",'Scenario 2 Raw'!$P$6:$P$155,"Excluded")+COUNTIFS('Scenario 2 Raw'!$B$6:$B$155,$B17,'Scenario 2 Raw'!$C$6:$C$155,"<>",'Scenario 2 Raw'!$P$6:$P$155,"Out of scope") -> 0 | H17: =COUNTIFS('Scenario 2 Raw'!$B$6:$B$155,$B17,'Scenario 2 Raw'!$C$6:$C$155,"<>",'Scenario 2 Raw'!$P$6:$P$155,"Duplicate / noise") -> 0 | I17: =COUNTIFS('Scenario 2 Raw'!$B$6:$B$155,$B17,'Scenario 2 Raw'!$C$6:$C$155,"<>",'Scenario 2 Raw'!$Q$6:$Q$155,"Yes",'Scenario 2 Raw'!$R$6:$R$155,"<>") -> 0 | J17: =IFERROR(F17/D17,0) -> 0 | K17: =IFERROR(I17/F17,0) -> 0
A18: Scenario 2 | B18: Microsoft TMT | C18: Threat-modeling tool | D18: =COUNTIFS('Scenario 2 Raw'!$B$6:$B$155,$B18,'Scenario 2 Raw'!$C$6:$C$155,"<>") -> 0 | E18: =COUNTIFS('Scenario 2 Raw'!$B$6:$B$155,$B18,'Scenario 2 Raw'!$C$6:$C$155,"<>",'Scenario 2 Raw'!$P$6:$P$155,"Reviewed") -> 0 | F18: =COUNTIFS('Scenario 2 Raw'!$B$6:$B$155,$B18,'Scenario 2 Raw'!$C$6:$C$155,"<>",'Scenario 2 Raw'!$Q$6:$Q$155,"Yes") -> 0 | G18: =COUNTIFS('Scenario 2 Raw'!$B$6:$B$155,$B18,'Scenario 2 Raw'!$C$6:$C$155,"<>",'Scenario 2 Raw'!$P$6:$P$155,"Excluded")+COUNTIFS('Scenario 2 Raw'!$B$6:$B$155,$B18,'Scenario 2 Raw'!$C$6:$C$155,"<>",'Scenario 2 Raw'!$P$6:$P$155,"Out of scope") -> 0 | H18: =COUNTIFS('Scenario 2 Raw'!$B$6:$B$155,$B18,'Scenario 2 Raw'!$C$6:$C$155,"<>",'Scenario 2 Raw'!$P$6:$P$155,"Duplicate / noise") -> 0 | I18: =COUNTIFS('Scenario 2 Raw'!$B$6:$B$155,$B18,'Scenario 2 Raw'!$C$6:$C$155,"<>",'Scenario 2 Raw'!$Q$6:$Q$155,"Yes",'Scenario 2 Raw'!$R$6:$R$155,"<>") -> 0 | J18: =IFERROR(F18/D18,0) -> 0 | K18: =IFERROR(I18/F18,0) -> 0
A19: Scenario 3 | B19: ChatGPT R1 | C19: LLM — ChatGPT | D19: =COUNTIFS('Scenario 3 Raw'!$B$6:$B$155,$B19,'Scenario 3 Raw'!$C$6:$C$155,"<>") -> 0 | E19: =COUNTIFS('Scenario 3 Raw'!$B$6:$B$155,$B19,'Scenario 3 Raw'!$C$6:$C$155,"<>",'Scenario 3 Raw'!$P$6:$P$155,"Reviewed") -> 0 | F19: =COUNTIFS('Scenario 3 Raw'!$B$6:$B$155,$B19,'Scenario 3 Raw'!$C$6:$C$155,"<>",'Scenario 3 Raw'!$Q$6:$Q$155,"Yes") -> 0 | G19: =COUNTIFS('Scenario 3 Raw'!$B$6:$B$155,$B19,'Scenario 3 Raw'!$C$6:$C$155,"<>",'Scenario 3 Raw'!$P$6:$P$155,"Excluded")+COUNTIFS('Scenario 3 Raw'!$B$6:$B$155,$B19,'Scenario 3 Raw'!$C$6:$C$155,"<>",'Scenario 3 Raw'!$P$6:$P$155,"Out of scope") -> 0 | H19: =COUNTIFS('Scenario 3 Raw'!$B$6:$B$155,$B19,'Scenario 3 Raw'!$C$6:$C$155,"<>",'Scenario 3 Raw'!$P$6:$P$155,"Duplicate / noise") -> 0 | I19: =COUNTIFS('Scenario 3 Raw'!$B$6:$B$155,$B19,'Scenario 3 Raw'!$C$6:$C$155,"<>",'Scenario 3 Raw'!$Q$6:$Q$155,"Yes",'Scenario 3 Raw'!$R$6:$R$155,"<>") -> 0 | J19: =IFERROR(F19/D19,0) -> 0 | K19: =IFERROR(I19/F19,0) -> 0
A20: Scenario 3 | B20: ChatGPT R2 | C20: LLM — ChatGPT | D20: =COUNTIFS('Scenario 3 Raw'!$B$6:$B$155,$B20,'Scenario 3 Raw'!$C$6:$C$155,"<>") -> 0 | E20: =COUNTIFS('Scenario 3 Raw'!$B$6:$B$155,$B20,'Scenario 3 Raw'!$C$6:$C$155,"<>",'Scenario 3 Raw'!$P$6:$P$155,"Reviewed") -> 0 | F20: =COUNTIFS('Scenario 3 Raw'!$B$6:$B$155,$B20,'Scenario 3 Raw'!$C$6:$C$155,"<>",'Scenario 3 Raw'!$Q$6:$Q$155,"Yes") -> 0 | G20: =COUNTIFS('Scenario 3 Raw'!$B$6:$B$155,$B20,'Scenario 3 Raw'!$C$6:$C$155,"<>",'Scenario 3 Raw'!$P$6:$P$155,"Excluded")+COUNTIFS('Scenario 3 Raw'!$B$6:$B$155,$B20,'Scenario 3 Raw'!$C$6:$C$155,"<>",'Scenario 3 Raw'!$P$6:$P$155,"Out of scope") -> 0 | H20: =COUNTIFS('Scenario 3 Raw'!$B$6:$B$155,$B20,'Scenario 3 Raw'!$C$6:$C$155,"<>",'Scenario 3 Raw'!$P$6:$P$155,"Duplicate / noise") -> 0 | I20: =COUNTIFS('Scenario 3 Raw'!$B$6:$B$155,$B20,'Scenario 3 Raw'!$C$6:$C$155,"<>",'Scenario 3 Raw'!$Q$6:$Q$155,"Yes",'Scenario 3 Raw'!$R$6:$R$155,"<>") -> 0 | J20: =IFERROR(F20/D20,0) -> 0 | K20: =IFERROR(I20/F20,0) -> 0
A21: Scenario 3 | B21: Llama R1 | C21: LLM — Llama | D21: =COUNTIFS('Scenario 3 Raw'!$B$6:$B$155,$B21,'Scenario 3 Raw'!$C$6:$C$155,"<>") -> 0 | E21: =COUNTIFS('Scenario 3 Raw'!$B$6:$B$155,$B21,'Scenario 3 Raw'!$C$6:$C$155,"<>",'Scenario 3 Raw'!$P$6:$P$155,"Reviewed") -> 0 | F21: =COUNTIFS('Scenario 3 Raw'!$B$6:$B$155,$B21,'Scenario 3 Raw'!$C$6:$C$155,"<>",'Scenario 3 Raw'!$Q$6:$Q$155,"Yes") -> 0 | G21: =COUNTIFS('Scenario 3 Raw'!$B$6:$B$155,$B21,'Scenario 3 Raw'!$C$6:$C$155,"<>",'Scenario 3 Raw'!$P$6:$P$155,"Excluded")+COUNTIFS('Scenario 3 Raw'!$B$6:$B$155,$B21,'Scenario 3 Raw'!$C$6:$C$155,"<>",'Scenario 3 Raw'!$P$6:$P$155,"Out of scope") -> 0 | H21: =COUNTIFS('Scenario 3 Raw'!$B$6:$B$155,$B21,'Scenario 3 Raw'!$C$6:$C$155,"<>",'Scenario 3 Raw'!$P$6:$P$155,"Duplicate / noise") -> 0 | I21: =COUNTIFS('Scenario 3 Raw'!$B$6:$B$155,$B21,'Scenario 3 Raw'!$C$6:$C$155,"<>",'Scenario 3 Raw'!$Q$6:$Q$155,"Yes",'Scenario 3 Raw'!$R$6:$R$155,"<>") -> 0 | J21: =IFERROR(F21/D21,0) -> 0 | K21: =IFERROR(I21/F21,0) -> 0
A22: Scenario 3 | B22: Llama R2 | C22: LLM — Llama | D22: =COUNTIFS('Scenario 3 Raw'!$B$6:$B$155,$B22,'Scenario 3 Raw'!$C$6:$C$155,"<>") -> 0 | E22: =COUNTIFS('Scenario 3 Raw'!$B$6:$B$155,$B22,'Scenario 3 Raw'!$C$6:$C$155,"<>",'Scenario 3 Raw'!$P$6:$P$155,"Reviewed") -> 0 | F22: =COUNTIFS('Scenario 3 Raw'!$B$6:$B$155,$B22,'Scenario 3 Raw'!$C$6:$C$155,"<>",'Scenario 3 Raw'!$Q$6:$Q$155,"Yes") -> 0 | G22: =COUNTIFS('Scenario 3 Raw'!$B$6:$B$155,$B22,'Scenario 3 Raw'!$C$6:$C$155,"<>",'Scenario 3 Raw'!$P$6:$P$155,"Excluded")+COUNTIFS('Scenario 3 Raw'!$B$6:$B$155,$B22,'Scenario 3 Raw'!$C$6:$C$155,"<>",'Scenario 3 Raw'!$P$6:$P$155,"Out of scope") -> 0 | H22: =COUNTIFS('Scenario 3 Raw'!$B$6:$B$155,$B22,'Scenario 3 Raw'!$C$6:$C$155,"<>",'Scenario 3 Raw'!$P$6:$P$155,"Duplicate / noise") -> 0 | I22: =COUNTIFS('Scenario 3 Raw'!$B$6:$B$155,$B22,'Scenario 3 Raw'!$C$6:$C$155,"<>",'Scenario 3 Raw'!$Q$6:$Q$155,"Yes",'Scenario 3 Raw'!$R$6:$R$155,"<>") -> 0 | J22: =IFERROR(F22/D22,0) -> 0 | K22: =IFERROR(I22/F22,0) -> 0
A23: Scenario 3 | B23: ThreMoLIA | C23: LLM-assisted threat-modeling tool | D23: =COUNTIFS('Scenario 3 Raw'!$B$6:$B$155,$B23,'Scenario 3 Raw'!$C$6:$C$155,"<>") -> 0 | E23: =COUNTIFS('Scenario 3 Raw'!$B$6:$B$155,$B23,'Scenario 3 Raw'!$C$6:$C$155,"<>",'Scenario 3 Raw'!$P$6:$P$155,"Reviewed") -> 0 | F23: =COUNTIFS('Scenario 3 Raw'!$B$6:$B$155,$B23,'Scenario 3 Raw'!$C$6:$C$155,"<>",'Scenario 3 Raw'!$Q$6:$Q$155,"Yes") -> 0 | G23: =COUNTIFS('Scenario 3 Raw'!$B$6:$B$155,$B23,'Scenario 3 Raw'!$C$6:$C$155,"<>",'Scenario 3 Raw'!$P$6:$P$155,"Excluded")+COUNTIFS('Scenario 3 Raw'!$B$6:$B$155,$B23,'Scenario 3 Raw'!$C$6:$C$155,"<>",'Scenario 3 Raw'!$P$6:$P$155,"Out of scope") -> 0 | H23: =COUNTIFS('Scenario 3 Raw'!$B$6:$B$155,$B23,'Scenario 3 Raw'!$C$6:$C$155,"<>",'Scenario 3 Raw'!$P$6:$P$155,"Duplicate / noise") -> 0 | I23: =COUNTIFS('Scenario 3 Raw'!$B$6:$B$155,$B23,'Scenario 3 Raw'!$C$6:$C$155,"<>",'Scenario 3 Raw'!$Q$6:$Q$155,"Yes",'Scenario 3 Raw'!$R$6:$R$155,"<>") -> 0 | J23: =IFERROR(F23/D23,0) -> 0 | K23: =IFERROR(I23/F23,0) -> 0
A24: Scenario 3 | B24: OWASP Threat Dragon | C24: Threat-modeling tool | D24: =COUNTIFS('Scenario 3 Raw'!$B$6:$B$155,$B24,'Scenario 3 Raw'!$C$6:$C$155,"<>") -> 0 | E24: =COUNTIFS('Scenario 3 Raw'!$B$6:$B$155,$B24,'Scenario 3 Raw'!$C$6:$C$155,"<>",'Scenario 3 Raw'!$P$6:$P$155,"Reviewed") -> 0 | F24: =COUNTIFS('Scenario 3 Raw'!$B$6:$B$155,$B24,'Scenario 3 Raw'!$C$6:$C$155,"<>",'Scenario 3 Raw'!$Q$6:$Q$155,"Yes") -> 0 | G24: =COUNTIFS('Scenario 3 Raw'!$B$6:$B$155,$B24,'Scenario 3 Raw'!$C$6:$C$155,"<>",'Scenario 3 Raw'!$P$6:$P$155,"Excluded")+COUNTIFS('Scenario 3 Raw'!$B$6:$B$155,$B24,'Scenario 3 Raw'!$C$6:$C$155,"<>",'Scenario 3 Raw'!$P$6:$P$155,"Out of scope") -> 0 | H24: =COUNTIFS('Scenario 3 Raw'!$B$6:$B$155,$B24,'Scenario 3 Raw'!$C$6:$C$155,"<>",'Scenario 3 Raw'!$P$6:$P$155,"Duplicate / noise") -> 0 | I24: =COUNTIFS('Scenario 3 Raw'!$B$6:$B$155,$B24,'Scenario 3 Raw'!$C$6:$C$155,"<>",'Scenario 3 Raw'!$Q$6:$Q$155,"Yes",'Scenario 3 Raw'!$R$6:$R$155,"<>") -> 0 | J24: =IFERROR(F24/D24,0) -> 0 | K24: =IFERROR(I24/F24,0) -> 0
A25: Scenario 3 | B25: Microsoft TMT | C25: Threat-modeling tool | D25: =COUNTIFS('Scenario 3 Raw'!$B$6:$B$155,$B25,'Scenario 3 Raw'!$C$6:$C$155,"<>") -> 0 | E25: =COUNTIFS('Scenario 3 Raw'!$B$6:$B$155,$B25,'Scenario 3 Raw'!$C$6:$C$155,"<>",'Scenario 3 Raw'!$P$6:$P$155,"Reviewed") -> 0 | F25: =COUNTIFS('Scenario 3 Raw'!$B$6:$B$155,$B25,'Scenario 3 Raw'!$C$6:$C$155,"<>",'Scenario 3 Raw'!$Q$6:$Q$155,"Yes") -> 0 | G25: =COUNTIFS('Scenario 3 Raw'!$B$6:$B$155,$B25,'Scenario 3 Raw'!$C$6:$C$155,"<>",'Scenario 3 Raw'!$P$6:$P$155,"Excluded")+COUNTIFS('Scenario 3 Raw'!$B$6:$B$155,$B25,'Scenario 3 Raw'!$C$6:$C$155,"<>",'Scenario 3 Raw'!$P$6:$P$155,"Out of scope") -> 0 | H25: =COUNTIFS('Scenario 3 Raw'!$B$6:$B$155,$B25,'Scenario 3 Raw'!$C$6:$C$155,"<>",'Scenario 3 Raw'!$P$6:$P$155,"Duplicate / noise") -> 0 | I25: =COUNTIFS('Scenario 3 Raw'!$B$6:$B$155,$B25,'Scenario 3 Raw'!$C$6:$C$155,"<>",'Scenario 3 Raw'!$Q$6:$Q$155,"Yes",'Scenario 3 Raw'!$R$6:$R$155,"<>") -> 0 | J25: =IFERROR(F25/D25,0) -> 0 | K25: =IFERROR(I25/F25,0) -> 0
A27: Interpretation note: mapping rate is the share of included records for which the analyst supplied a cross-approach mapping ID. It is not a precision, recall or accuracy estimate.

Sheet STRIDE Summary
A1: STRIDE / Category Summary
A2: Included findings only, compared across all LLM runs and threat-modeling tools.
A4: Scenario | B4: Approach | C4: STRIDE category | D4: Included findings | E4: Share of approach included | F4: Interpretive note (manual)
A5: Scenario 1 | B5: ChatGPT R1 | C5: Spoofing | D5: =COUNTIFS('Scenario 1 Raw'!$B$6:$B$155,$B5,'Scenario 1 Raw'!$C$6:$C$155,"<>",'Scenario 1 Raw'!$Q$6:$Q$155,"Yes",'Scenario 1 Raw'!$K$6:$K$155,$C5) -> 0 | E5: =IFERROR(D5/COUNTIFS('Scenario 1 Raw'!$B$6:$B$155,$B5,'Scenario 1 Raw'!$C$6:$C$155,"<>",'Scenario 1 Raw'!$Q$6:$Q$155,"Yes"),0) -> 0
A6: Scenario 1 | B6: ChatGPT R1 | C6: Tampering | D6: =COUNTIFS('Scenario 1 Raw'!$B$6:$B$155,$B6,'Scenario 1 Raw'!$C$6:$C$155,"<>",'Scenario 1 Raw'!$Q$6:$Q$155,"Yes",'Scenario 1 Raw'!$K$6:$K$155,$C6) -> 0 | E6: =IFERROR(D6/COUNTIFS('Scenario 1 Raw'!$B$6:$B$155,$B6,'Scenario 1 Raw'!$C$6:$C$155,"<>",'Scenario 1 Raw'!$Q$6:$Q$155,"Yes"),0) -> 0
A7: Scenario 1 | B7: ChatGPT R1 | C7: Repudiation | D7: =COUNTIFS('Scenario 1 Raw'!$B$6:$B$155,$B7,'Scenario 1 Raw'!$C$6:$C$155,"<>",'Scenario 1 Raw'!$Q$6:$Q$155,"Yes",'Scenario 1 Raw'!$K$6:$K$155,$C7) -> 0 | E7: =IFERROR(D7/COUNTIFS('Scenario 1 Raw'!$B$6:$B$155,$B7,'Scenario 1 Raw'!$C$6:$C$155,"<>",'Scenario 1 Raw'!$Q$6:$Q$155,"Yes"),0) -> 0
A8: Scenario 1 | B8: ChatGPT R1 | C8: Information Disclosure | D8: =COUNTIFS('Scenario 1 Raw'!$B$6:$B$155,$B8,'Scenario 1 Raw'!$C$6:$C$155,"<>",'Scenario 1 Raw'!$Q$6:$Q$155,"Yes",'Scenario 1 Raw'!$K$6:$K$155,$C8) -> 0 | E8: =IFERROR(D8/COUNTIFS('Scenario 1 Raw'!$B$6:$B$155,$B8,'Scenario 1 Raw'!$C$6:$C$155,"<>",'Scenario 1 Raw'!$Q$6:$Q$155,"Yes"),0) -> 0
A9: Scenario 1 | B9: ChatGPT R1 | C9: Denial of Service | D9: =COUNTIFS('Scenario 1 Raw'!$B$6:$B$155,$B9,'Scenario 1 Raw'!$C$6:$C$155,"<>",'Scenario 1 Raw'!$Q$6:$Q$155,"Yes",'Scenario 1 Raw'!$K$6:$K$155,$C9) -> 0 | E9: =IFERROR(D9/COUNTIFS('Scenario 1 Raw'!$B$6:$B$155,$B9,'Scenario 1 Raw'!$C$6:$C$155,"<>",'Scenario 1 Raw'!$Q$6:$Q$155,"Yes"),0) -> 0
A10: Scenario 1 | B10: ChatGPT R1 | C10: Elevation of Privilege | D10: =COUNTIFS('Scenario 1 Raw'!$B$6:$B$155,$B10,'Scenario 1 Raw'!$C$6:$C$155,"<>",'Scenario 1 Raw'!$Q$6:$Q$155,"Yes",'Scenario 1 Raw'!$K$6:$K$155,$C10) -> 0 | E10: =IFERROR(D10/COUNTIFS('Scenario 1 Raw'!$B$6:$B$155,$B10,'Scenario 1 Raw'!$C$6:$C$155,"<>",'Scenario 1 Raw'!$Q$6:$Q$155,"Yes"),0) -> 0
A11: Scenario 1 | B11: ChatGPT R2 | C11: Spoofing | D11: =COUNTIFS('Scenario 1 Raw'!$B$6:$B$155,$B11,'Scenario 1 Raw'!$C$6:$C$155,"<>",'Scenario 1 Raw'!$Q$6:$Q$155,"Yes",'Scenario 1 Raw'!$K$6:$K$155,$C11) -> 0 | E11: =IFERROR(D11/COUNTIFS('Scenario 1 Raw'!$B$6:$B$155,$B11,'Scenario 1 Raw'!$C$6:$C$155,"<>",'Scenario 1 Raw'!$Q$6:$Q$155,"Yes"),0) -> 0
A12: Scenario 1 | B12: ChatGPT R2 | C12: Tampering | D12: =COUNTIFS('Scenario 1 Raw'!$B$6:$B$155,$B12,'Scenario 1 Raw'!$C$6:$C$155,"<>",'Scenario 1 Raw'!$Q$6:$Q$155,"Yes",'Scenario 1 Raw'!$K$6:$K$155,$C12) -> 0 | E12: =IFERROR(D12/COUNTIFS('Scenario 1 Raw'!$B$6:$B$155,$B12,'Scenario 1 Raw'!$C$6:$C$155,"<>",'Scenario 1 Raw'!$Q$6:$Q$155,"Yes"),0) -> 0
A13: Scenario 1 | B13: ChatGPT R2 | C13: Repudiation | D13: =COUNTIFS('Scenario 1 Raw'!$B$6:$B$155,$B13,'Scenario 1 Raw'!$C$6:$C$155,"<>",'Scenario 1 Raw'!$Q$6:$Q$155,"Yes",'Scenario 1 Raw'!$K$6:$K$155,$C13) -> 0 | E13: =IFERROR(D13/COUNTIFS('Scenario 1 Raw'!$B$6:$B$155,$B13,'Scenario 1 Raw'!$C$6:$C$155,"<>",'Scenario 1 Raw'!$Q$6:$Q$155,"Yes"),0) -> 0
A14: Scenario 1 | B14: ChatGPT R2 | C14: Information Disclosure | D14: =COUNTIFS('Scenario 1 Raw'!$B$6:$B$155,$B14,'Scenario 1 Raw'!$C$6:$C$155,"<>",'Scenario 1 Raw'!$Q$6:$Q$155,"Yes",'Scenario 1 Raw'!$K$6:$K$155,$C14) -> 0 | E14: =IFERROR(D14/COUNTIFS('Scenario 1 Raw'!$B$6:$B$155,$B14,'Scenario 1 Raw'!$C$6:$C$155,"<>",'Scenario 1 Raw'!$Q$6:$Q$155,"Yes"),0) -> 0
A15: Scenario 1 | B15: ChatGPT R2 | C15: Denial of Service | D15: =COUNTIFS('Scenario 1 Raw'!$B$6:$B$155,$B15,'Scenario 1 Raw'!$C$6:$C$155,"<>",'Scenario 1 Raw'!$Q$6:$Q$155,"Yes",'Scenario 1 Raw'!$K$6:$K$155,$C15) -> 0 | E15: =IFERROR(D15/COUNTIFS('Scenario 1 Raw'!$B$6:$B$155,$B15,'Scenario 1 Raw'!$C$6:$C$155,"<>",'Scenario 1 Raw'!$Q$6:$Q$155,"Yes"),0) -> 0
A16: Scenario 1 | B16: ChatGPT R2 | C16: Elevation of Privilege | D16: =COUNTIFS('Scenario 1 Raw'!$B$6:$B$155,$B16,'Scenario 1 Raw'!$C$6:$C$155,"<>",'Scenario 1 Raw'!$Q$6:$Q$155,"Yes",'Scenario 1 Raw'!$K$6:$K$155,$C16) -> 0 | E16: =IFERROR(D16/COUNTIFS('Scenario 1 Raw'!$B$6:$B$155,$B16,'Scenario 1 Raw'!$C$6:$C$155,"<>",'Scenario 1 Raw'!$Q$6:$Q$155,"Yes"),0) -> 0
... A46: Scenario 1 | B46: Microsoft TMT | C46: Elevation of Privilege | D46: =COUNTIFS('Scenario 1 Raw'!$B$6:$B$155,$B46,'Scenario 1 Raw'!$C$6:$C$155,"<>",'Scenario 1 Raw'!$Q$6:$Q$155,"Yes",'Scenario 1 Raw'!$K$6:$K$155,$C46) -> 0 | E46: =IFERROR(D46/COUNTIFS('Scenario 1 Raw'!$B$6:$B$155,$B46,'Scenario 1 Raw'!$C$6:$C$155,"<>",'Scenario 1 Raw'!$Q$6:$Q$155,"Yes"),0) -> 0
A47: Scenario 2 | B47: ChatGPT R1 | C47: Spoofing | D47: =COUNTIFS('Scenario 2 Raw'!$B$6:$B$155,$B47,'Scenario 2 Raw'!$C$6:$C$155,"<>",'Scenario 2 Raw'!$Q$6:$Q$155,"Yes",'Scenario 2 Raw'!$K$6:$K$155,$C47) -> 0 | E47: =IFERROR(D47/COUNTIFS('Scenario 2 Raw'!$B$6:$B$155,$B47,'Scenario 2 Raw'!$C$6:$C$155,"<>",'Scenario 2 Raw'!$Q$6:$Q$155,"Yes"),0) -> 0
A48: Scenario 2 | B48: ChatGPT R1 | C48: Tampering | D48: =COUNTIFS('Scenario 2 Raw'!$B$6:$B$155,$B48,'Scenario 2 Raw'!$C$6:$C$155,"<>",'Scenario 2 Raw'!$Q$6:$Q$155,"Yes",'Scenario 2 Raw'!$K$6:$K$155,$C48) -> 0 | E48: =IFERROR(D48/COUNTIFS('Scenario 2 Raw'!$B$6:$B$155,$B48,'Scenario 2 Raw'!$C$6:$C$155,"<>",'Scenario 2 Raw'!$Q$6:$Q$155,"Yes"),0) -> 0
A49: Scenario 2 | B49: ChatGPT R1 | C49: Repudiation | D49: =COUNTIFS('Scenario 2 Raw'!$B$6:$B$155,$B49,'Scenario 2 Raw'!$C$6:$C$155,"<>",'Scenario 2 Raw'!$Q$6:$Q$155,"Yes",'Scenario 2 Raw'!$K$6:$K$155,$C49) -> 0 | E49: =IFERROR(D49/COUNTIFS('Scenario 2 Raw'!$B$6:$B$155,$B49,'Scenario 2 Raw'!$C$6:$C$155,"<>",'Scenario 2 Raw'!$Q$6:$Q$155,"Yes"),0) -> 0
A50: Scenario 2 | B50: ChatGPT R1 | C50: Information Disclosure | D50: =COUNTIFS('Scenario 2 Raw'!$B$6:$B$155,$B50,'Scenario 2 Raw'!$C$6:$C$155,"<>",'Scenario 2 Raw'!$Q$6:$Q$155,"Yes",'Scenario 2 Raw'!$K$6:$K$155,$C50) -> 0 | E50: =IFERROR(D50/COUNTIFS('Scenario 2 Raw'!$B$6:$B$155,$B50,'Scenario 2 Raw'!$C$6:$C$155,"<>",'Scenario 2 Raw'!$Q$6:$Q$155,"Yes"),0) -> 0
A51: Scenario 2 | B51: ChatGPT R1 | C51: Denial of Service | D51: =COUNTIFS('Scenario 2 Raw'!$B$6:$B$155,$B51,'Scenario 2 Raw'!$C$6:$C$155,"<>",'Scenario 2 Raw'!$Q$6:$Q$155,"Yes",'Scenario 2 Raw'!$K$6:$K$155,$C51) -> 0 | E51: =IFERROR(D51/COUNTIFS('Scenario 2 Raw'!$B$6:$B$155,$B51,'Scenario 2 Raw'!$C$6:$C$155,"<>",'Scenario 2 Raw'!$Q$6:$Q$155,"Yes"),0) -> 0
A52: Scenario 2 | B52: ChatGPT R1 | C52: Elevation of Privilege | D52: =COUNTIFS('Scenario 2 Raw'!$B$6:$B$155,$B52,'Scenario 2 Raw'!$C$6:$C$155,"<>",'Scenario 2 Raw'!$Q$6:$Q$155,"Yes",'Scenario 2 Raw'!$K$6:$K$155,$C52) -> 0 | E52: =IFERROR(D52/COUNTIFS('Scenario 2 Raw'!$B$6:$B$155,$B52,'Scenario 2 Raw'!$C$6:$C$155,"<>",'Scenario 2 Raw'!$Q$6:$Q$155,"Yes"),0) -> 0
A53: Scenario 2 | B53: ChatGPT R2 | C53: Spoofing | D53: =COUNTIFS('Scenario 2 Raw'!$B$6:$B$155,$B53,'Scenario 2 Raw'!$C$6:$C$155,"<>",'Scenario 2 Raw'!$Q$6:$Q$155,"Yes",'Scenario 2 Raw'!$K$6:$K$155,$C53) -> 0 | E53: =IFERROR(D53/COUNTIFS('Scenario 2 Raw'!$B$6:$B$155,$B53,'Scenario 2 Raw'!$C$6:$C$155,"<>",'Scenario 2 Raw'!$Q$6:$Q$155,"Yes"),0) -> 0
A54: Scenario 2 | B54: ChatGPT R2 | C54: Tampering | D54: =COUNTIFS('Scenario 2 Raw'!$B$6:$B$155,$B54,'Scenario 2 Raw'!$C$6:$C$155,"<>",'Scenario 2 Raw'!$Q$6:$Q$155,"Yes",'Scenario 2 Raw'!$K$6:$K$155,$C54) -> 0 | E54: =IFERROR(D54/COUNTIFS('Scenario 2 Raw'!$B$6:$B$155,$B54,'Scenario 2 Raw'!$C$6:$C$155,"<>",'Scenario 2 Raw'!$Q$6:$Q$155,"Yes"),0) -> 0
A55: Scenario 2 | B55: ChatGPT R2 | C55: Repudiation | D55: =COUNTIFS('Scenario 2 Raw'!$B$6:$B$155,$B55,'Scenario 2 Raw'!$C$6:$C$155,"<>",'Scenario 2 Raw'!$Q$6:$Q$155,"Yes",'Scenario 2 Raw'!$K$6:$K$155,$C55) -> 0 | E55: =IFERROR(D55/COUNTIFS('Scenario 2 Raw'!$B$6:$B$155,$B55,'Scenario 2 Raw'!$C$6:$C$155,"<>",'Scenario 2 Raw'!$Q$6:$Q$155,"Yes"),0) -> 0
A56: Scenario 2 | B56: ChatGPT R2 | C56: Information Disclosure | D56: =COUNTIFS('Scenario 2 Raw'!$B$6:$B$155,$B56,'Scenario 2 Raw'!$C$6:$C$155,"<>",'Scenario 2 Raw'!$Q$6:$Q$155,"Yes",'Scenario 2 Raw'!$K$6:$K$155,$C56) -> 0 | E56: =IFERROR(D56/COUNTIFS('Scenario 2 Raw'!$B$6:$B$155,$B56,'Scenario 2 Raw'!$C$6:$C$155,"<>",'Scenario 2 Raw'!$Q$6:$Q$155,"Yes"),0) -> 0
A57: Scenario 2 | B57: ChatGPT R2 | C57: Denial of Service | D57: =COUNTIFS('Scenario 2 Raw'!$B$6:$B$155,$B57,'Scenario 2 Raw'!$C$6:$C$155,"<>",'Scenario 2 Raw'!$Q$6:$Q$155,"Yes",'Scenario 2 Raw'!$K$6:$K$155,$C57) -> 0 | E57: =IFERROR(D57/COUNTIFS('Scenario 2 Raw'!$B$6:$B$155,$B57,'Scenario 2 Raw'!$C$6:$C$155,"<>",'Scenario 2 Raw'!$Q$6:$Q$155,"Yes"),0) -> 0
A58: Scenario 2 | B58: ChatGPT R2 | C58: Elevation of Privilege | D58: =COUNTIFS('Scenario 2 Raw'!$B$6:$B$155,$B58,'Scenario 2 Raw'!$C$6:$C$155,"<>",'Scenario 2 Raw'!$Q$6:$Q$155,"Yes",'Scenario 2 Raw'!$K$6:$K$155,$C58) -> 0 | E58: =IFERROR(D58/COUNTIFS('Scenario 2 Raw'!$B$6:$B$155,$B58,'Scenario 2 Raw'!$C$6:$C$155,"<>",'Scenario 2 Raw'!$Q$6:$Q$155,"Yes"),0) -> 0
... A88: Scenario 2 | B88: Microsoft TMT | C88: Elevation of Privilege | D88: =COUNTIFS('Scenario 2 Raw'!$B$6:$B$155,$B88,'Scenario 2 Raw'!$C$6:$C$155,"<>",'Scenario 2 Raw'!$Q$6:$Q$155,"Yes",'Scenario 2 Raw'!$K$6:$K$155,$C88) -> 0 | E88: =IFERROR(D88/COUNTIFS('Scenario 2 Raw'!$B$6:$B$155,$B88,'Scenario 2 Raw'!$C$6:$C$155,"<>",'Scenario 2 Raw'!$Q$6:$Q$155,"Yes"),0) -> 0
A89: Scenario 3 | B89: ChatGPT R1 | C89: Spoofing | D89: =COUNTIFS('Scenario 3 Raw'!$B$6:$B$155,$B89,'Scenario 3 Raw'!$C$6:$C$155,"<>",'Scenario 3 Raw'!$Q$6:$Q$155,"Yes",'Scenario 3 Raw'!$K$6:$K$155,$C89) -> 0 | E89: =IFERROR(D89/COUNTIFS('Scenario 3 Raw'!$B$6:$B$155,$B89,'Scenario 3 Raw'!$C$6:$C$155,"<>",'Scenario 3 Raw'!$Q$6:$Q$155,"Yes"),0) -> 0
A90: Scenario 3 | B90: ChatGPT R1 | C90: Tampering | D90: =COUNTIFS('Scenario 3 Raw'!$B$6:$B$155,$B90,'Scenario 3 Raw'!$C$6:$C$155,"<>",'Scenario 3 Raw'!$Q$6:$Q$155,"Yes",'Scenario 3 Raw'!$K$6:$K$155,$C90) -> 0 | E90: =IFERROR(D90/COUNTIFS('Scenario 3 Raw'!$B$6:$B$155,$B90,'Scenario 3 Raw'!$C$6:$C$155,"<>",'Scenario 3 Raw'!$Q$6:$Q$155,"Yes"),0) -> 0
A91: Scenario 3 | B91: ChatGPT R1 | C91: Repudiation | D91: =COUNTIFS('Scenario 3 Raw'!$B$6:$B$155,$B91,'Scenario 3 Raw'!$C$6:$C$155,"<>",'Scenario 3 Raw'!$Q$6:$Q$155,"Yes",'Scenario 3 Raw'!$K$6:$K$155,$C91) -> 0 | E91: =IFERROR(D91/COUNTIFS('Scenario 3 Raw'!$B$6:$B$155,$B91,'Scenario 3 Raw'!$C$6:$C$155,"<>",'Scenario 3 Raw'!$Q$6:$Q$155,"Yes"),0) -> 0
A92: Scenario 3 | B92: ChatGPT R1 | C92: Information Disclosure | D92: =COUNTIFS('Scenario 3 Raw'!$B$6:$B$155,$B92,'Scenario 3 Raw'!$C$6:$C$155,"<>",'Scenario 3 Raw'!$Q$6:$Q$155,"Yes",'Scenario 3 Raw'!$K$6:$K$155,$C92) -> 0 | E92: =IFERROR(D92/COUNTIFS('Scenario 3 Raw'!$B$6:$B$155,$B92,'Scenario 3 Raw'!$C$6:$C$155,"<>",'Scenario 3 Raw'!$Q$6:$Q$155,"Yes"),0) -> 0
A93: Scenario 3 | B93: ChatGPT R1 | C93: Denial of Service | D93: =COUNTIFS('Scenario 3 Raw'!$B$6:$B$155,$B93,'Scenario 3 Raw'!$C$6:$C$155,"<>",'Scenario 3 Raw'!$Q$6:$Q$155,"Yes",'Scenario 3 Raw'!$K$6:$K$155,$C93) -> 0 | E93: =IFERROR(D93/COUNTIFS('Scenario 3 Raw'!$B$6:$B$155,$B93,'Scenario 3 Raw'!$C$6:$C$155,"<>",'Scenario 3 Raw'!$Q$6:$Q$155,"Yes"),0) -> 0
A94: Scenario 3 | B94: ChatGPT R1 | C94: Elevation of Privilege | D94: =COUNTIFS('Scenario 3 Raw'!$B$6:$B$155,$B94,'Scenario 3 Raw'!$C$6:$C$155,"<>",'Scenario 3 Raw'!$Q$6:$Q$155,"Yes",'Scenario 3 Raw'!$K$6:$K$155,$C94) -> 0 | E94: =IFERROR(D94/COUNTIFS('Scenario 3 Raw'!$B$6:$B$155,$B94,'Scenario 3 Raw'!$C$6:$C$155,"<>",'Scenario 3 Raw'!$Q$6:$Q$155,"Yes"),0) -> 0
A95: Scenario 3 | B95: ChatGPT R2 | C95: Spoofing | D95: =COUNTIFS('Scenario 3 Raw'!$B$6:$B$155,$B95,'Scenario 3 Raw'!$C$6:$C$155,"<>",'Scenario 3 Raw'!$Q$6:$Q$155,"Yes",'Scenario 3 Raw'!$K$6:$K$155,$C95) -> 0 | E95: =IFERROR(D95/COUNTIFS('Scenario 3 Raw'!$B$6:$B$155,$B95,'Scenario 3 Raw'!$C$6:$C$155,"<>",'Scenario 3 Raw'!$Q$6:$Q$155,"Yes"),0) -> 0
A96: Scenario 3 | B96: ChatGPT R2 | C96: Tampering | D96: =COUNTIFS('Scenario 3 Raw'!$B$6:$B$155,$B96,'Scenario 3 Raw'!$C$6:$C$155,"<>",'Scenario 3 Raw'!$Q$6:$Q$155,"Yes",'Scenario 3 Raw'!$K$6:$K$155,$C96) -> 0 | E96: =IFERROR(D96/COUNTIFS('Scenario 3 Raw'!$B$6:$B$155,$B96,'Scenario 3 Raw'!$C$6:$C$155,"<>",'Scenario 3 Raw'!$Q$6:$Q$155,"Yes"),0) -> 0
A97: Scenario 3 | B97: ChatGPT R2 | C97: Repudiation | D97: =COUNTIFS('Scenario 3 Raw'!$B$6:$B$155,$B97,'Scenario 3 Raw'!$C$6:$C$155,"<>",'Scenario 3 Raw'!$Q$6:$Q$155,"Yes",'Scenario 3 Raw'!$K$6:$K$155,$C97) -> 0 | E97: =IFERROR(D97/COUNTIFS('Scenario 3 Raw'!$B$6:$B$155,$B97,'Scenario 3 Raw'!$C$6:$C$155,"<>",'Scenario 3 Raw'!$Q$6:$Q$155,"Yes"),0) -> 0
A98: Scenario 3 | B98: ChatGPT R2 | C98: Information Disclosure | D98: =COUNTIFS('Scenario 3 Raw'!$B$6:$B$155,$B98,'Scenario 3 Raw'!$C$6:$C$155,"<>",'Scenario 3 Raw'!$Q$6:$Q$155,"Yes",'Scenario 3 Raw'!$K$6:$K$155,$C98) -> 0 | E98: =IFERROR(D98/COUNTIFS('Scenario 3 Raw'!$B$6:$B$155,$B98,'Scenario 3 Raw'!$C$6:$C$155,"<>",'Scenario 3 Raw'!$Q$6:$Q$155,"Yes"),0) -> 0
A99: Scenario 3 | B99: ChatGPT R2 | C99: Denial of Service | D99: =COUNTIFS('Scenario 3 Raw'!$B$6:$B$155,$B99,'Scenario 3 Raw'!$C$6:$C$155,"<>",'Scenario 3 Raw'!$Q$6:$Q$155,"Yes",'Scenario 3 Raw'!$K$6:$K$155,$C99) -> 0 | E99: =IFERROR(D99/COUNTIFS('Scenario 3 Raw'!$B$6:$B$155,$B99,'Scenario 3 Raw'!$C$6:$C$155,"<>",'Scenario 3 Raw'!$Q$6:$Q$155,"Yes"),0) -> 0
...

Sheet LLM Coverage
A1: LLM-Specific Coverage
A2: Use this to compare LLM-related threat coverage across ChatGPT, Llama, ThreMoLIA and the two DFD tools. Included findings only.
A4: Scenario | B4: Approach | C4: LLM theme | D4: Included findings | E4: Share of approach LLM findings | F4: Interpretive note (manual)
A5: Scenario 1 | B5: ChatGPT R1 | C5: Prompt injection | D5: =COUNTIFS('Scenario 1 Raw'!$B$6:$B$155,$B5,'Scenario 1 Raw'!$C$6:$C$155,"<>",'Scenario 1 Raw'!$Q$6:$Q$155,"Yes",'Scenario 1 Raw'!$M$6:$M$155,"Yes",'Scenario 1 Raw'!$N$6:$N$155,$C5) -> 0 | E5: =IFERROR(D5/COUNTIFS('Scenario 1 Raw'!$B$6:$B$155,$B5,'Scenario 1 Raw'!$C$6:$C$155,"<>",'Scenario 1 Raw'!$Q$6:$Q$155,"Yes",'Scenario 1 Raw'!$M$6:$M$155,"Yes"),0) -> 0
A6: Scenario 1 | B6: ChatGPT R1 | C6: Insecure output handling | D6: =COUNTIFS('Scenario 1 Raw'!$B$6:$B$155,$B6,'Scenario 1 Raw'!$C$6:$C$155,"<>",'Scenario 1 Raw'!$Q$6:$Q$155,"Yes",'Scenario 1 Raw'!$M$6:$M$155,"Yes",'Scenario 1 Raw'!$N$6:$N$155,$C6) -> 0 | E6: =IFERROR(D6/COUNTIFS('Scenario 1 Raw'!$B$6:$B$155,$B6,'Scenario 1 Raw'!$C$6:$C$155,"<>",'Scenario 1 Raw'!$Q$6:$Q$155,"Yes",'Scenario 1 Raw'!$M$6:$M$155,"Yes"),0) -> 0
A7: Scenario 1 | B7: ChatGPT R1 | C7: Sensitive data disclosure | D7: =COUNTIFS('Scenario 1 Raw'!$B$6:$B$155,$B7,'Scenario 1 Raw'!$C$6:$C$155,"<>",'Scenario 1 Raw'!$Q$6:$Q$155,"Yes",'Scenario 1 Raw'!$M$6:$M$155,"Yes",'Scenario 1 Raw'!$N$6:$N$155,$C7) -> 0 | E7: =IFERROR(D7/COUNTIFS('Scenario 1 Raw'!$B$6:$B$155,$B7,'Scenario 1 Raw'!$C$6:$C$155,"<>",'Scenario 1 Raw'!$Q$6:$Q$155,"Yes",'Scenario 1 Raw'!$M$6:$M$155,"Yes"),0) -> 0
A8: Scenario 1 | B8: ChatGPT R1 | C8: Third-party LLM exposure | D8: =COUNTIFS('Scenario 1 Raw'!$B$6:$B$155,$B8,'Scenario 1 Raw'!$C$6:$C$155,"<>",'Scenario 1 Raw'!$Q$6:$Q$155,"Yes",'Scenario 1 Raw'!$M$6:$M$155,"Yes",'Scenario 1 Raw'!$N$6:$N$155,$C8) -> 0 | E8: =IFERROR(D8/COUNTIFS('Scenario 1 Raw'!$B$6:$B$155,$B8,'Scenario 1 Raw'!$C$6:$C$155,"<>",'Scenario 1 Raw'!$Q$6:$Q$155,"Yes",'Scenario 1 Raw'!$M$6:$M$155,"Yes"),0) -> 0
A9: Scenario 1 | B9: ChatGPT R1 | C9: Model / service denial of service | D9: =COUNTIFS('Scenario 1 Raw'!$B$6:$B$155,$B9,'Scenario 1 Raw'!$C$6:$C$155,"<>",'Scenario 1 Raw'!$Q$6:$Q$155,"Yes",'Scenario 1 Raw'!$M$6:$M$155,"Yes",'Scenario 1 Raw'!$N$6:$N$155,$C9) -> 0 | E9: =IFERROR(D9/COUNTIFS('Scenario 1 Raw'!$B$6:$B$155,$B9,'Scenario 1 Raw'!$C$6:$C$155,"<>",'Scenario 1 Raw'!$Q$6:$Q$155,"Yes",'Scenario 1 Raw'!$M$6:$M$155,"Yes"),0) -> 0
A10: Scenario 1 | B10: ChatGPT R1 | C10: Knowledge-base or supply-chain poisoning | D10: =COUNTIFS('Scenario 1 Raw'!$B$6:$B$155,$B10,'Scenario 1 Raw'!$C$6:$C$155,"<>",'Scenario 1 Raw'!$Q$6:$Q$155,"Yes",'Scenario 1 Raw'!$M$6:$M$155,"Yes",'Scenario 1 Raw'!$N$6:$N$155,$C10) -> 0 | E10: =IFERROR(D10/COUNTIFS('Scenario 1 Raw'!$B$6:$B$155,$B10,'Scenario 1 Raw'!$C$6:$C$155,"<>",'Scenario 1 Raw'!$Q$6:$Q$155,"Yes",'Scenario 1 Raw'!$M$6:$M$155,"Yes"),0) -> 0
A11: Scenario 1 | B11: ChatGPT R1 | C11: LLM authorization / context isolation | D11: =COUNTIFS('Scenario 1 Raw'!$B$6:$B$155,$B11,'Scenario 1 Raw'!$C$6:$C$155,"<>",'Scenario 1 Raw'!$Q$6:$Q$155,"Yes",'Scenario 1 Raw'!$M$6:$M$155,"Yes",'Scenario 1 Raw'!$N$6:$N$155,$C11) -> 0 | E11: =IFERROR(D11/COUNTIFS('Scenario 1 Raw'!$B$6:$B$155,$B11,'Scenario 1 Raw'!$C$6:$C$155,"<>",'Scenario 1 Raw'!$Q$6:$Q$155,"Yes",'Scenario 1 Raw'!$M$6:$M$155,"Yes"),0) -> 0
A12: Scenario 1 | B12: ChatGPT R2 | C12: Prompt injection | D12: =COUNTIFS('Scenario 1 Raw'!$B$6:$B$155,$B12,'Scenario 1 Raw'!$C$6:$C$155,"<>",'Scenario 1 Raw'!$Q$6:$Q$155,"Yes",'Scenario 1 Raw'!$M$6:$M$155,"Yes",'Scenario 1 Raw'!$N$6:$N$155,$C12) -> 0 | E12: =IFERROR(D12/COUNTIFS('Scenario 1 Raw'!$B$6:$B$155,$B12,'Scenario 1 Raw'!$C$6:$C$155,"<>",'Scenario 1 Raw'!$Q$6:$Q$155,"Yes",'Scenario 1 Raw'!$M$6:$M$155,"Yes"),0) -> 0
A13: Scenario 1 | B13: ChatGPT R2 | C13: Insecure output handling | D13: =COUNTIFS('Scenario 1 Raw'!$B$6:$B$155,$B13,'Scenario 1 Raw'!$C$6:$C$155,"<>",'Scenario 1 Raw'!$Q$6:$Q$155,"Yes",'Scenario 1 Raw'!$M$6:$M$155,"Yes",'Scenario 1 Raw'!$N$6:$N$155,$C13) -> 0 | E13: =IFERROR(D13/COUNTIFS('Scenario 1 Raw'!$B$6:$B$155,$B13,'Scenario 1 Raw'!$C$6:$C$155,"<>",'Scenario 1 Raw'!$Q$6:$Q$155,"Yes",'Scenario 1 Raw'!$M$6:$M$155,"Yes"),0) -> 0
A14: Scenario 1 | B14: ChatGPT R2 | C14: Sensitive data disclosure | D14: =COUNTIFS('Scenario 1 Raw'!$B$6:$B$155,$B14,'Scenario 1 Raw'!$C$6:$C$155,"<>",'Scenario 1 Raw'!$Q$6:$Q$155,"Yes",'Scenario 1 Raw'!$M$6:$M$155,"Yes",'Scenario 1 Raw'!$N$6:$N$155,$C14) -> 0 | E14: =IFERROR(D14/COUNTIFS('Scenario 1 Raw'!$B$6:$B$155,$B14,'Scenario 1 Raw'!$C$6:$C$155,"<>",'Scenario 1 Raw'!$Q$6:$Q$155,"Yes",'Scenario 1 Raw'!$M$6:$M$155,"Yes"),0) -> 0
A15: Scenario 1 | B15: ChatGPT R2 | C15: Third-party LLM exposure | D15: =COUNTIFS('Scenario 1 Raw'!$B$6:$B$155,$B15,'Scenario 1 Raw'!$C$6:$C$155,"<>",'Scenario 1 Raw'!$Q$6:$Q$155,"Yes",'Scenario 1 Raw'!$M$6:$M$155,"Yes",'Scenario 1 Raw'!$N$6:$N$155,$C15) -> 0 | E15: =IFERROR(D15/COUNTIFS('Scenario 1 Raw'!$B$6:$B$155,$B15,'Scenario 1 Raw'!$C$6:$C$155,"<>",'Scenario 1 Raw'!$Q$6:$Q$155,"Yes",'Scenario 1 Raw'!$M$6:$M$155,"Yes"),0) -> 0
A16: Scenario 1 | B16: ChatGPT R2 | C16: Model / service denial of service | D16: =COUNTIFS('Scenario 1 Raw'!$B$6:$B$155,$B16,'Scenario 1 Raw'!$C$6:$C$155,"<>",'Scenario 1 Raw'!$Q$6:$Q$155,"Yes",'Scenario 1 Raw'!$M$6:$M$155,"Yes",'Scenario 1 Raw'!$N$6:$N$155,$C16) -> 0 | E16: =IFERROR(D16/COUNTIFS('Scenario 1 Raw'!$B$6:$B$155,$B16,'Scenario 1 Raw'!$C$6:$C$155,"<>",'Scenario 1 Raw'!$Q$6:$Q$155,"Yes",'Scenario 1 Raw'!$M$6:$M$155,"Yes"),0) -> 0
... A53: Scenario 1 | B53: Microsoft TMT | C53: LLM authorization / context isolation | D53: =COUNTIFS('Scenario 1 Raw'!$B$6:$B$155,$B53,'Scenario 1 Raw'!$C$6:$C$155,"<>",'Scenario 1 Raw'!$Q$6:$Q$155,"Yes",'Scenario 1 Raw'!$M$6:$M$155,"Yes",'Scenario 1 Raw'!$N$6:$N$155,$C53) -> 0 | E53: =IFERROR(D53/COUNTIFS('Scenario 1 Raw'!$B$6:$B$155,$B53,'Scenario 1 Raw'!$C$6:$C$155,"<>",'Scenario 1 Raw'!$Q$6:$Q$155,"Yes",'Scenario 1 Raw'!$M$6:$M$155,"Yes"),0) -> 0
A54: Scenario 2 | B54: ChatGPT R1 | C54: Prompt injection | D54: =COUNTIFS('Scenario 2 Raw'!$B$6:$B$155,$B54,'Scenario 2 Raw'!$C$6:$C$155,"<>",'Scenario 2 Raw'!$Q$6:$Q$155,"Yes",'Scenario 2 Raw'!$M$6:$M$155,"Yes",'Scenario 2 Raw'!$N$6:$N$155,$C54) -> 0 | E54: =IFERROR(D54/COUNTIFS('Scenario 2 Raw'!$B$6:$B$155,$B54,'Scenario 2 Raw'!$C$6:$C$155,"<>",'Scenario 2 Raw'!$Q$6:$Q$155,"Yes",'Scenario 2 Raw'!$M$6:$M$155,"Yes"),0) -> 0
A55: Scenario 2 | B55: ChatGPT R1 | C55: Insecure output handling | D55: =COUNTIFS('Scenario 2 Raw'!$B$6:$B$155,$B55,'Scenario 2 Raw'!$C$6:$C$155,"<>",'Scenario 2 Raw'!$Q$6:$Q$155,"Yes",'Scenario 2 Raw'!$M$6:$M$155,"Yes",'Scenario 2 Raw'!$N$6:$N$155,$C55) -> 0 | E55: =IFERROR(D55/COUNTIFS('Scenario 2 Raw'!$B$6:$B$155,$B55,'Scenario 2 Raw'!$C$6:$C$155,"<>",'Scenario 2 Raw'!$Q$6:$Q$155,"Yes",'Scenario 2 Raw'!$M$6:$M$155,"Yes"),0) -> 0
A56: Scenario 2 | B56: ChatGPT R1 | C56: Sensitive data disclosure | D56: =COUNTIFS('Scenario 2 Raw'!$B$6:$B$155,$B56,'Scenario 2 Raw'!$C$6:$C$155,"<>",'Scenario 2 Raw'!$Q$6:$Q$155,"Yes",'Scenario 2 Raw'!$M$6:$M$155,"Yes",'Scenario 2 Raw'!$N$6:$N$155,$C56) -> 0 | E56: =IFERROR(D56/COUNTIFS('Scenario 2 Raw'!$B$6:$B$155,$B56,'Scenario 2 Raw'!$C$6:$C$155,"<>",'Scenario 2 Raw'!$Q$6:$Q$155,"Yes",'Scenario 2 Raw'!$M$6:$M$155,"Yes"),0) -> 0
