Workbook

Sheet 00_README
A1: FINAL Master Workbook — LLM-Assisted Threat Modeling Evaluation (CORRECTED)
A2: Single source of truth for quantitative thesis results. All derived values are live Excel formulas; nothing derived is hard-coded.
A4: PURPOSE: This workbook is the audited, corrected version of the master evaluation workbook. It has been rebuilt from the authoritative source artifacts so that every final metric is traceable back through the calculation sheet -> TP/FP/FN -> per-finding mapping -> generated finding -> original source, and every Recall value is traceable to the expert reference baseline.
A5: AUDIT AUTHORITY (important): 1) Expert reference baselines (Scenario{1,2,3}_Expert_Reference_Baseline_FINAL.csv) are treated as the authoritative comparison baseline (NOT as infallible truth). 2) matching.csv is treated as the authoritative per-finding matching decision record (one row per generated finding). 3) The previously-exported PDF workbook displayed a TP/FP/Duplicate set that does NOT match matching.csv; this discrepancy is flagged in 15_DATA_QUALITY and Section A/C of the audit report.
A6: AUDIT ASSUMPTIONS: (a) One-to-one rule implemented: within each Approach x Scenario a reference threat contributes exactly one Primary TP; additional equivalent findings are Duplicates. (b) Recall = Primary TP / Reference threats; Duplicates do NOT add recall. (c) Precision follows the stated formula TP/(TP+FP) using Primary TP; a supplementary "per-finding precision incl. duplicates" is also shown. (d) Metrics that the source data cannot support are reported as N/A and FLAGGED, never fabricated.
A7: MISSING DATA (flagged N/A): (1) Per-finding GROUNDING annotation - not provided -> 08_GROUNDING = N/A. (2) Approach FEATURE/FUNCTIONALITY matrix - documentation not provided -> all cells "Unknown", feature completeness & MCDM composite = N/A. (3) Per-finding STRIDE classification for False-Positive findings - not provided -> STRIDE precision/FP/Generated = N/A (STRIDE recall computed at reference level). (4) No SUS/usability study - no SUS scores computed.
A8: TERMINOLOGY: OWASP = OWASP Threat Dragon; TMT = Microsoft Threat Modeling Tool; CHATGPT = ChatGPT; OLLAMA = Ollama (local LLM); THREMOLIA = ThreMoLIA.
A9: COLOUR KEY: BLUE = raw generated data (verbatim). GREEN = validated reference baseline. YELLOW = manual matching/mapping coding. RED = failed check. GREY = fixed parameters/metadata.
A10: STATISTICAL CAVEAT: There are only three scenarios (n=3). The 1,025 generated findings are NOT treated as independent statistical observations; scenario-level descriptive statistics are the primary analysis. No inferential tests were performed.
A11: METHODOLOGICAL RULES: See 15_DATA_QUALITY, 16_CHANGE_LOG and this README. Rules: one-to-one rule; semantic (not keyword) matching; Precision=TP/(TP+FP); Recall=TP/Reference; FN=Reference-TP; F1 harmonic; no accuracy/TN; grounding separate from correctness; severity only from baseline; MCDM = decision-support synthesis (30/30/20/20), not a statistical metric.
A12: DISCLAIMER: The workbook is not claimed to be perfect. Unresolved items are listed in 15_DATA_QUALITY and in the accompanying audit report (AUDIT_REPORT.md).

Sheet 01_SCENARIOS
A1: Scenario Architecture and Volume Overview
A2: All counts are formulas over 02_REFERENCE / 03_RAW_FINDINGS / 04_MATCHING.
A4: Scenario | B4: Scenario Name | C4: Reference threats | D4: LLM-specific refs | E4: OWASP | F4: TMT | G4: CHATGPT | H4: OLLAMA | I4: THREMOLIA | J4: Total findings
A5: S1 | B5: S1 - User authentication web app with AI chatbot assistant | C5: =COUNTIFS('02_REFERENCE'!$B$2:$B$99,$A5,'02_REFERENCE'!$S$2:$S$99,"YES") -> 32 | D5: =COUNTIFS('02_REFERENCE'!$B$2:$B$99,$A5,'02_REFERENCE'!$S$2:$S$99,"YES",'02_REFERENCE'!$Q$2:$Q$99,"Yes") -> 13 | E5: =COUNTIFS('04_MATCHING'!$B$2:$B$1026,"OWASP",'04_MATCHING'!$C$2:$C$1026,$A5) -> 38 | F5: =COUNTIFS('04_MATCHING'!$B$2:$B$1026,"TMT",'04_MATCHING'!$C$2:$C$1026,$A5) -> 95 | G5: =COUNTIFS('04_MATCHING'!$B$2:$B$1026,"CHATGPT",'04_MATCHING'!$C$2:$C$1026,$A5) -> 72 | H5: =COUNTIFS('04_MATCHING'!$B$2:$B$1026,"OLLAMA",'04_MATCHING'!$C$2:$C$1026,$A5) -> 40 | I5: =COUNTIFS('04_MATCHING'!$B$2:$B$1026,"THREMOLIA",'04_MATCHING'!$C$2:$C$1026,$A5) -> 106 | J5: =SUM(E5:I5) -> 351
A6: S2 | B6: S2 - Secure file management platform with AI file assistant (external LLM) | C6: =COUNTIFS('02_REFERENCE'!$B$2:$B$99,$A6,'02_REFERENCE'!$S$2:$S$99,"YES") -> 33 | D6: =COUNTIFS('02_REFERENCE'!$B$2:$B$99,$A6,'02_REFERENCE'!$S$2:$S$99,"YES",'02_REFERENCE'!$Q$2:$Q$99,"Yes") -> 13 | E6: =COUNTIFS('04_MATCHING'!$B$2:$B$1026,"OWASP",'04_MATCHING'!$C$2:$C$1026,$A6) -> 39 | F6: =COUNTIFS('04_MATCHING'!$B$2:$B$1026,"TMT",'04_MATCHING'!$C$2:$C$1026,$A6) -> 89 | G6: =COUNTIFS('04_MATCHING'!$B$2:$B$1026,"CHATGPT",'04_MATCHING'!$C$2:$C$1026,$A6) -> 60 | H6: =COUNTIFS('04_MATCHING'!$B$2:$B$1026,"OLLAMA",'04_MATCHING'!$C$2:$C$1026,$A6) -> 28 | I6: =COUNTIFS('04_MATCHING'!$B$2:$B$1026,"THREMOLIA",'04_MATCHING'!$C$2:$C$1026,$A6) -> 105 | J6: =SUM(E6:I6) -> 321
A7: S3 | B7: S3 - Account recovery & profile management with AI support assistant (external LLM) | C7: =COUNTIFS('02_REFERENCE'!$B$2:$B$99,$A7,'02_REFERENCE'!$S$2:$S$99,"YES") -> 33 | D7: =COUNTIFS('02_REFERENCE'!$B$2:$B$99,$A7,'02_REFERENCE'!$S$2:$S$99,"YES",'02_REFERENCE'!$Q$2:$Q$99,"Yes") -> 12 | E7: =COUNTIFS('04_MATCHING'!$B$2:$B$1026,"OWASP",'04_MATCHING'!$C$2:$C$1026,$A7) -> 46 | F7: =COUNTIFS('04_MATCHING'!$B$2:$B$1026,"TMT",'04_MATCHING'!$C$2:$C$1026,$A7) -> 117 | G7: =COUNTIFS('04_MATCHING'!$B$2:$B$1026,"CHATGPT",'04_MATCHING'!$C$2:$C$1026,$A7) -> 49 | H7: =COUNTIFS('04_MATCHING'!$B$2:$B$1026,"OLLAMA",'04_MATCHING'!$C$2:$C$1026,$A7) -> 24 | I7: =COUNTIFS('04_MATCHING'!$B$2:$B$1026,"THREMOLIA",'04_MATCHING'!$C$2:$C$1026,$A7) -> 117 | J7: =SUM(E7:I7) -> 353
A8: TOTAL | B8: Grand total (three scenarios, five approaches) | C8: =SUM(C5:C7) -> 98 | D8: =SUM(D5:D7) -> 38 | E8: =SUM(E5:E7) -> 123 | F8: =SUM(F5:F7) -> 301 | G8: =SUM(G5:G7) -> 181 | H8: =SUM(H5:H7) -> 92 | I8: =SUM(I5:I7) -> 328 | J8: =SUM(J5:J7) -> 1025
A10: Architecture note
A11: TMT and ThreMoLIA model the architectures with different element/flow identifiers (TMT decomposes services; ThreMoLIA uses its own DF/SF numbering). Matching (04) is semantic, never identifier-based. Each scenario's reference baseline is frozen as provided.

Sheet 02_REFERENCE
A1: Expert Reference Baseline (98 threats)
A2: S1-RT-001 | B2: S1 | C2: Online brute-force password guessing | D2: Spoofing | E2: Authentication | F2: P2 Authentication Service (reached via P1 Web Frontend) | G2: DF1, DF2, DF3 | H2: TB1 | I2: User credentials; authentication decision | J2: Unbounded automated password guessing against the credential verification path: the attacker iterates candidate passwords for a known username until the verification result on DF4 indicates success; anti-automation is not specified by the architecture anywhere between the DF1 entry point and the DF3 verification cycle. | K2: An attacker obtains a valid username through enumeration (S1-RT-003), then scripts repeated login submissions on DF1, each carrying the same username with the next candidate password. P1 forwards every attempt on DF2, P2 executes a DF3 verification against DS1 for each, and no element in the drawn architecture limits attempt count or frequency. On the first successful verification the attacker receives a session token via DF6 and holds the account. | L2: Account takeover: one guessed password yields a valid session token on DF6, because the architecture specifies credential verification as the sole authentication factor and no second factor or step-up mechanism is drawn anywhere. | M2: P2 is the sole authentication decision authority (stated assumption A1) and is anonymously reachable because DF1 crosses TB1 from the untrusted End User environment. The DF2 to DF3 verification cycle is unbounded in the drawn architecture: no anti-automation or attempt-limiting element is specified on any flow. OWASP A07 places anti-automation at exactly this point. | N2: Final audit: retained. Architecture-grounded (DF1, DF2, DF3, TB1, A1); distinct from S1-RT-002, which is breadth-first replay of breached pairs rather than depth-first guessing; objectively matchable by attack pattern. Primary STRIDE is Spoofing: the attacker presents a credential they do not own in order to be recognised as the account owner. Control-gap phrasing applied per rule 7: anti-automation is described as not specified, not as definitely absent. Evaluation note: if lockout-style anti-automation is implemented, it admits its own denial-of-access abuse vector, which is documented in the audit summary rather than retained as a separate architecture-level threat. | O2: High | P2: High | Q2: No | R2: High | S2: YES
A3: S1-RT-002 | B3: S1 | C3: Credential stuffing using breached credential corpora | D3: Spoofing | E3: Authentication | F3: P2 Authentication Service | G3: DF1, DF2 | H3: TB1 | I3: User credentials; user accounts | J3: Distributed low-rate replay of externally breached username and password pairs across many accounts and sources, producing a per-account request pattern that per-account anti-automation, where implemented at all, does not detect. | K3: The attacker loads a corpus of breached credential pairs and submits each pair exactly once per account, distributed across many sources. Every account sees at most one failed DF3 verification, so any per-account attempt limit never trips; every password the victim reuses elsewhere yields a session token on DF6 for the attacker. | L3: Mass account takeover proportional to the password-reuse rate in the user population, with a session token issued on DF6 for every successful pair. | M3: Like S1-RT-001 this exploits the anonymous reachability of DF1 across TB1 into P2, but the attack path is breadth-first across accounts rather than depth-first against one, producing a statistically different DF2 request pattern; OWASP treats stuffing and brute force as distinct techniques with distinct controls (breached-password screening versus attempt limiting). | N3: Final audit: retained. Distinct mechanism from S1-RT-001 (request pattern, detection signal and control all differ), so the pair is not merged. Primary STRIDE is Spoofing: valid credentials of the real owner are used to impersonate them. Conditional phrasing applied: the presence of any attempt-limiting control is treated as unspecified, and the mechanism is stated as the pattern such controls fail to catch. | O3: High | P3: High | Q3: No | R3: High | S3: YES
A4: S1-RT-003 | B4: S1 | C4: Username and account enumeration | D4: Information Disclosure | E4: Authentication | F4: P2 Authentication Service; P1 Web Frontend | G4: DF1, DF2, DF4 | H4: TB1 | I4: Account existence metadata (PII) | J4: Differential response content, status or timing between existing and non-existing accounts turns the login and registration functions into an account-existence oracle whose signal crosses TB1 to the untrusted user environment. | K4: The attacker submits login attempts for candidate usernames with a fixed wrong password and compares the returned responses: an account-specific response for existing usernames versus a generic one for non-existing usernames, or a measurable timing difference carried by the DF4 result through P2 and P1, confirms which accounts exist before any guessing begins. | L4: Produces a validated target list that raises the yield of S1-RT-001 and S1-RT-002, and discloses membership information about identifiable persons. | M4: The verification outcome produced on DF4 propagates back through P2 and P1 and crosses TB1 to the untrusted user environment; response uniformity is not specified by the architecture, so differentiating responses are an architecture-level exposure rather than an implementation accident. ASVS V2.2 requires uniform authentication responses at exactly this point. | N4: Final audit: retained. An enabler rather than a direct compromise (Severity Medium) but a distinct mechanism, a design-level response oracle, separable from S1-RT-019 (diagnostic-content disclosure) by inspection method and asset. Primary STRIDE is Information Disclosure: the leaked asset is account existence metadata. No implementation assumption is required: the oracle is defined by response differentiation across a drawn boundary. | O4: Medium | P4: High | Q4: No | R4: High | S4: YES
A5: S1-RT-004 | B5: S1 | C5: Authentication bypass through flawed authentication logic | D5: Spoofing | E5: Authentication | F5: P2 Authentication Service; P3 Session Management Module | G5: DF2, DF5 | H5: TB1; internal P2-to-P3 transition | I5: Authentication decision; session tokens | J5: Request manipulation reaches session creation on DF5 without a successful verification result: forged or mishandled verification state passed from P2 to P3, or direct invocation of the P3 session-creation function where it is independently reachable. | K5: The attacker submits crafted login content that causes P2 to pass an incomplete or mishandled verification result to the session-creation step, or invokes P3's session-creation function directly with a chosen identity; P3 issues a token on DF6 for an arbitrary account whose credentials were never verified against DS1. | L5: Complete authentication bypass: a valid session token is issued on DF6 for an arbitrary identity without any credential ever being verified, defeating the architecture's central property that P2 alone decides authentication. | M5: Nothing in the drawn architecture forces DF5 to be preceded by a successful DF3/DF4 verification; the ordering constraint is an implementation convention rather than an enforced control, and the attacker input that drives the bypass enters across TB1 on DF1 and DF2. Stated assumption A1 makes P2 the sole authentication authority, so any path to DF5 around verification defeats a stated property with no drawn enforcement point. OWASP A04 (insecure design) applies. | N5: Final audit: retained. Primary STRIDE is Spoofing: an unverified identity is accepted as an authenticated subject, which is the essence of spoofing; elevation of privilege is the downstream consequence when privileged accounts are targeted and is retained as a secondary note here only. Implementation-specific payload examples (type-confusion values) were removed; the mechanism is stated at the level of the unenforced DF3/DF4-before-DF5 ordering, which the drawn architecture fully supports. Severity Critical: the bypass mints sessions for arbitrary identities. | O5: Critical | P5: Medium | Q5: No | R5: High | S5: YES
A6: S1-RT-006 | B6: S1 | C6: Exposure of credentials in transit on the authentication paths | D6: Information Disclosure | E6: Authentication | F6: P1 Web Frontend; P2 Authentication Service | G6: DF1, DF2 | H6: TB1 (external leg); internal P1-to-P2 leg | I6: User credentials | J6: Credentials in plaintext form traverse DF1 across TB1 and the internal DF2 leg, and confidentiality protection for these flows is not specified by the architecture; an actor positioned on either path reads submitted credentials. | K6: An actor positioned on the communication path between the End User and P1, or between P1 and P2, reads the username and password of every login submission traversing DF1 and DF2. Any implementation-side persistence of flow content, which the architecture does not specify, would extend the same exposure to stored artefacts and is treated as conditional. | L6: Direct exposure of plaintext passwords, enabling immediate account takeover and cross-service reuse independent of any guessing. | M6: DF1 and DF2 are the only flows in the model that carry plaintext credentials; DF1 crosses TB1 into the application; no confidentiality control for either flow is specified anywhere in the architecture, and under A6 that unspecified protection is itself the architecture-level finding. OWASP A02 applies. | N6: Final audit: retained with a technology-neutral rewrite. The first-pass wording referenced transport-security mechanisms and logging artefacts that the architecture does not specify; the mechanism is now stated purely as unprotected credential-bearing flows across drawn boundaries, with persistence-based exposure phrased conditionally (rules 1 and 7). Distinct from S1-RT-001 and S1-RT-002: credentials are captured rather than guessed. Primary STRIDE is Information Disclosure. | O6: High | P6: High | Q6: No | R6: High | S6: YES
A7: S1-RT-008 | B7: S1 | C7: Injection into the credential verification exchange | D7: Tampering | E7: Authorization | F7: P2 Authentication Service; DS1 User Database | G7: DF3, DF4 | H7: TB3 | I7: User credentials; password hashes; authentication decision | J7: Untrusted input submitted on DF1 influences the verification request that P2 composes on DF3, altering what DS1 returns on DF4: the store result can be forced positive, or the exchange can be steered to return stored records beyond the intended lookup. | K7: The attacker submits a crafted username whose content changes the semantics of the DF3 verification request so that the DF4 response indicates success without the correct password; the same flaw is then steered to return stored credential records from DS1 instead of a single verification result. | L7: Simultaneous authentication bypass and mass disclosure of usernames and password hashes, the worst combined confidentiality and access-control outcome available in this architecture. | M7: DF3, issued by P2 against DS1, is the only flow in the model where untrusted text that entered P1 across TB1 is transformed into a request interpreted by a higher-authority component across TB3; the taint path DF1 to DF2 to DF3 contains no validation or separation element, a confused-deputy condition at the TB3 crossing. OWASP A03 applies. | N7: Final audit: retained with a technology-neutral rewrite: implementation-specific injection constructs were removed, and the mechanism is stated as untrusted influence over the DF3/DF4 verification exchange, which the drawn architecture fully supports. Matching note: a candidate threat describing injection into the session-validation lookups on SF1/SF3 matches this entry, since the taint pattern and the mitigation class are identical. Primary STRIDE is Tampering: the integrity of the verification request is violated; bypass and extraction are consequences. | O7: Critical | P7: Medium | Q7: No | R7: High | S7: YES
A8: S1-RT-009 | B8: S1 | C8: Excessive database access scope across the application-to-database boundary | D8: Elevation of Privilege | E8: Authorization | F8: Application services and store layer (P2, P3, P4 interacting with DS1, DS2, DS3) | G8: DF3, DF4, SF1, SF2 | H8: TB3 | I8: User credentials; session tokens; LLM context repository | J8: Access scoping at the TB3 crossing is not specified by the architecture: nothing requires that each service's store access be limited to the store it legitimately uses, so a compromised or defective service can read and write stores it never requires. | K8: An attacker who compromises P4 operates with its store access; because no per-service scoping is specified, the attacker reaches DS1 and DS2, password hashes and session tokens, although P4 legitimately requires only DS3. | L8: Compromise of any one application service yields read or write access to stores it does not need, so a defect in a lower-value service exposes authentication credentials in DS1 or session tokens in DS2. | M8: TB3 exists to ensure that access to authentication and session data is subject to controlled authorisation. The model shows three distinct services crossing TB3 towards three distinct stores with disjoint legitimate needs: P2 to DS1 on DF3/DF4, P3 to DS2 on SF1, and P4 to DS3 on SF2; how access is scoped at that crossing is not specified, which is recorded as an architecture-level control gap. | N8: Final audit: retained with control-gap phrasing (rule 7): the entry states that scoping is not specified rather than claiming a specific misconfiguration. The entry makes no claim that the chatbot accesses the authentication databases: the architecture states the opposite, and access scoping is the control that keeps that stated property true under component compromise. Distinct from S1-RT-017, which addresses direct compromise of the session store itself. Primary STRIDE is Elevation of Privilege. | O8: High | P8: Medium | Q8: No | R8: High | S8: YES
A9: S1-RT-010 | B9: S1 | C9: Broken object-level authorisation on account data | D9: Elevation of Privilege | E9: Authorization | F9: P2 Authentication Service; P1 Web Frontend | G9: DF2, DF3, DF4 | H9: TB1; TB3 | I9: Account information (PII); authentication decision | J9: An authenticated user substitutes another user's identifier in an account request, and P2 composes the DF3 request from the client-supplied identifier rather than from the identity bound to the authenticated session. | K9: After logging in normally, the attacker submits an account-information request naming a victim's identifier; P2 queries DS1 on DF3 using the supplied identifier and returns or modifies the victim's account record, because no element binds the DF3 access to the identity established at authentication. | L9: Unauthorised read or modification of other users' account information held in DS1. | M9: Identity is established when DF4 returns a successful verification result, but the drawn architecture contains no enforcement element that binds subsequent DS1 access on DF3 to that established identity; authentication and authorisation are therefore separable in this design, and a request may cross TB1 with a valid session and still address another subject's data across TB3. OWASP A01 applies. | N9: Final audit: retained. Primary STRIDE is Elevation of Privilege: the attacker accesses an object belonging to another subject; information disclosure is the consequence and is noted as secondary here only. The grounding is absence-based (no authorisation-enforcement element is drawn), which is stated as a control gap rather than a definite flaw, hence Confidence Medium. Objectively matchable: any candidate threat describing unauthorised access to another user's account record through identifier substitution matches. | O9: High | P9: High | Q9: No | R9: Medium | S9: YES
A10: S1-RT-011 | B10: S1 | C10: Missing authorisation on the chatbot interface | D10: Elevation of Privilege | E10: Authorization | F10: P4 AI Chatbot Component | G10: DF7, SF3 | H10: TB1 | I10: LLM context; generated responses; provider quota | J10: The chatbot interface is invoked directly rather than through the user interface, without presenting a valid session token, or the SF3 validation step is absent or advisory only, so the LLM pipeline is reachable without authentication. | K10: An unauthenticated client calls the chatbot entry point directly, bypassing the web interface; P4 accepts the question on DF7, retrieves context on SF2, and P5 spends provider quota on DF9, all without a session token ever being presented or validated through SF3. | L10: Anonymous consumption of the downstream LLM pipeline, exposure of approved context and assistant behaviour to unauthenticated parties, and loss of per-user attribution for abuse. | M10: DF7 runs from the untrusted End User directly to P4 and crosses TB1 independently of the DF1-to-DF6 authentication path, so P4 does not inherit any protection established at login; SF3, the session-token validation exchange between P3 and P4, is the only authorisation element on this path, and its enforcement strength is not specified. P4's stated responsibilities include no identity check of its own. | N10: Final audit: retained. Primary STRIDE is Elevation of Privilege: the attacker uses a protected application capability without any entitlement; no identity is forged, so Spoofing is not the primary violation. Classified as not LLM-specific: the defect is a missing access-control check on an application endpoint and would exist identically if P4 served static content. Conditional phrasing applied to the SF3 enforcement strength. Objectively matchable by the unauthenticated-reachability test. | O10: High | P10: Medium | Q10: No | R10: High | S10: YES
A11: S1-RT-012 | B11: S1 | C11: Cross-user context leakage between chatbot sessions | D11: Information Disclosure | E11: Authorization | F11: P4 AI Chatbot Component; P5 LLM Integration Service | G11: DF7, DF8, DF11, DF12 | H11: TB1 | I11: User prompts; LLM context; generated responses | J11: A shared or incorrectly keyed conversation-context buffer causes one user's prior questions or retrieved context to be incorporated into another user's prompt on DF8, or a concurrency defect causes a response on DF11 to be delivered to the wrong requester on DF12. | K11: Two users question the chatbot concurrently; a context buffer keyed incorrectly under load causes user B's assembled prompt on DF8 to include user A's earlier authentication-related questions, and the generated answer is delivered to the wrong requester on DF12 with the application's authority. | L11: Disclosure of one user's authentication-related questions and identifiers to a different user, delivered with the application's authority. | M11: P4 and P5 are single logical processes serving all users, and neither DF8 nor DF11 carries an explicit per-user key in the model; conversation context is required for coherent multi-turn answers yet is not represented as a data store in the architecture, so its isolation is not specified, and the leaked material crosses TB1 to the wrong subject on DF12. | N11: Final audit: retained. AI-specific because the leaked asset is accumulated AI context that exists only because prompts are assembled from conversational state. Distinct from S1-RT-026 (authorised aggregate interrogation, components behaving as designed) and from S1-RT-024 (egress to the provider): here the defect is internal keying or concurrency, and the isolation of the unrepresented context store is stated as an architecture-level gap. Confidence Medium for that reason. | O11: Medium | P11: Medium | Q11: Yes | R11: Medium | S11: YES
A12: S1-RT-013 | B12: S1 | C12: Session fixation on the authentication flow | D12: Spoofing | E12: Session Management | F12: P1 Web Frontend Interface; P3 Session Management Module | G12: DF1, DF5, DF6, SF1 | H12: TB1; TB3 | I12: Session tokens; authenticated sessions | J12: Nothing in the architecture requires that the session identifier issued at the authentication transition be freshly derived: if an identifier the attacker already knows is accepted at DF5, P3 binds the victim's authenticated identity to that pre-existing value instead of generating a fresh one for DF6. | K12: The attacker supplies the victim with an authentication entry point that carries an attacker-chosen session identifier (the mechanism by which identifiers travel to the client is not specified by the architecture); the victim authenticates through it; P3 binds the authenticated identity to the known value, and from the moment login completes the attacker uses that identifier as the victim. | L12: The attacker holds a valid token for the victim's authenticated session from the moment login completes, without observing credentials, predicting a generated value, or intercepting any flow. | M12: Token generation is an explicitly stated responsibility of P3, but the drawn flow set shows creation (DF5), issuance (DF6) and persistence (SF1) without any element requiring that the issued identifier be freshly derived at the authentication transition, so acceptance of a client-influenced identifier is an uncontrolled degree of freedom; ASVS V3.2 requires regeneration at every authentication transition. | N12: Final audit: retained with a technology-neutral rewrite: client-transport mechanisms for identifiers were removed, and the acceptance of a client-influenced identifier is phrased conditionally because identifier transport is not specified (rules 1 and 7). Retained separately from S1-RT-014, S1-RT-015 and S1-RT-016 because the attacker never acquires, computes or reuses a token: the victim authenticates onto an identifier the attacker already holds, a distinct control failure with a distinct mitigation. Primary STRIDE is Spoofing. | O12: High | P12: Medium | Q12: No | R12: High | S12: YES
A13: S1-RT-014 | B13: S1 | C13: Session token theft at the delivery and persistence crossings | D13: Spoofing | E13: Session Management | F13: P3 Session Management Module; P1 Web Frontend; DS2 Session Storage | G13: DF6, SF1 | H13: TB1; TB3 | I13: Session tokens | J13: The bearer token is exposed at its two drawn crossings: at delivery to the client environment on DF6 across TB1, where protection of the token within the client context is not specified, and at persistence to DS2 on SF1 across TB3, where store-side protection is not specified; a captured token is presented as the victim. | K13: Script executing in the victim's client environment, delivered for instance through S1-RT-033, reads the session token where it is exposed to client-side code and exfiltrates it; the attacker presents the token from their own client and operates as the victim for the remaining token lifetime. | L13: Full session hijack: the attacker acts as the victim without possessing credentials, defeating password strength and every login-time control. | M13: The session token is a bearer secret exposed at two distinct boundaries with two distinct control sets: it crosses TB1 on DF6 when delivered to the client, and TB3 on SF1 when persisted to DS2; neither crossing has a specified protection, and no element in the model protects either leg specifically. | N13: Final audit: retained with a technology-neutral rewrite: implementation-specific client-side protections were removed and replaced with the unspecified-protection phrasing for both drawn crossings (rules 1 and 7). Primary STRIDE is Spoofing: the primary violation is unauthorised use of the victim's authenticated session; the capture enabling it is information disclosure, noted as secondary. Both crossings are kept so that a partial mitigation at one boundary is not mistaken for coverage. Severity Critical: terminal node of the injection-to-takeover chain anchored by S1-RT-033. | O13: Critical | P13: Medium | Q13: No | R13: High | S13: YES
... A99: S3-RT-034 | B99: S3 | C99: Profile updates performed without valid recovery authorisation | D99: Elevation of Privilege | E99: Authorization | F99: P3 Profile Management Service; P2 Account Recovery Service | G99: DF8, DF9 (the authorisation precondition's enforcement point is not represented in the model) | H99: TB3 | I99: Profile information; user account information; integrity of the recovery-authorisation precondition | J99: The architecture states that P3 performs updates only after authorised recovery approval, but no flow or element shows how P3 establishes that approval: no P2-to-P3 authorisation flow is drawn, and no consultation of DS2's token state by P3 is represented. If the implementation accepts update requests on DF8 without verifiable proof of a valid recovery authorisation, profile modification is available without the recovery the precondition exists to enforce. | K99: An attacker submits a profile update request on DF8 with no completed recovery behind it — the authorisation precondition absent, forged, or merely asserted in the request; P3 persists the change to DS1 on DF9, and the modification stands although no recovery was ever authorised for the account. | L99: Unauthorised profile modification that bypasses the recovery-authorisation gate entirely, collapsing the stated ordering — recovery first, update after — and arming the downstream paths that manipulated profile data enables, including S3-RT-013 and the recovery arming of S3-RT-008. | M99: A1 makes P2 the only recovery authorisation authority, and the supplied architecture makes authorised recovery approval the stated precondition of every P3 update, yet the model draws neither a flow conveying that approval to P3 nor any P3-side check of it; a stated security property without a represented enforcement point is an architecture-level gap the reference model must record, in the same manner as the token-redemption binding gap of S3-RT-006. | N99: NEW ENTRY added in this review. Reason: the profile-management checklist requires coverage of modification without valid recovery authorisation, and the catalogue's existing profile entries attack record selection (S3-RT-007), field scope (S3-RT-008) and store access (S3-RT-009) but not the precondition itself; the mechanism here is the missing enforcement of the recovery-authorisation gate at P3, which is distinct from all three and admits a distinct mitigation, verifiable authorisation proof bound to the update request. Absence-justified rather than drawn-flow-justified, hence Confidence Medium. Primary STRIDE is Elevation of Privilege: a protected capability is exercised without entitlement. Severity High; Likelihood Medium. Not LLM-specific. | O99: High | P99: Medium | Q99: No | R99: Medium | S99: YES

Sheet 03_RAW_FINDINGS
A1: Raw Generated Findings (1,025, verbatim)
A2: OWASP-S1-F001 | B2: OWASP | C2: S1 | D2: captcha | E2: CAPTCHA defeat | F2: EE1 End User | H2: OWASP/S1
A3: OWASP-S1-F002 | B3: OWASP | C3: S1 | D3: credential_stuffing | E3: Credential stuffing | F3: EE1 End User | H3: OWASP/S1
A4: OWASP-S1-F003 | B4: OWASP | C4: S1 | D4: excessive_db_scope | E4: Least privilege | F4: P1 Web Frontend Interface | H4: OWASP/S1
A5: OWASP-S1-F004 | B5: OWASP | C5: S1 | D5: expedition | E5: Expedition | F5: P1 Web Frontend Interface | H5: OWASP/S1
A6: OWASP-S1-F005 | B6: OWASP | C6: S1 | D6: recon | E6: Vulnerability scanning | F6: P1 Web Frontend Interface | H6: OWASP/S1
A7: OWASP-S1-F006 | B7: OWASP | C7: S1 | D7: dos_service | E7: Denial of Service | F7: P1 Web Frontend Interface | H7: OWASP/S1
A8: OWASP-S1-F007 | B8: OWASP | C8: S1 | D8: recon | E8: Footprinting | F8: P1 Web Frontend Interface | H8: OWASP/S1
A9: OWASP-S1-F008 | B9: OWASP | C9: S1 | D9: excessive_db_scope | E9: Least privilege | F9: P2 Authentication Service | H9: OWASP/S1
A10: OWASP-S1-F009 | B10: OWASP | C10: S1 | D10: expedition | E10: Expedition | F10: P2 Authentication Service | H10: OWASP/S1
A11: OWASP-S1-F010 | B11: OWASP | C11: S1 | D11: recon | E11: Vulnerability scanning | F11: P2 Authentication Service | H11: OWASP/S1
A12: OWASP-S1-F011 | B12: OWASP | C12: S1 | D12: dos_service | E12: Denial of Service | F12: P2 Authentication Service | H12: OWASP/S1
A13: OWASP-S1-F012 | B13: OWASP | C13: S1 | D13: recon | E13: Footprinting | F13: P2 Authentication Service | H13: OWASP/S1
... A39: OWASP-S1-F038 | B39: OWASP | C39: S1 | D39: stored_prompt_injection | E39: Spamming | F39: DS3 Knowledge Base | H39: OWASP/S1
A40: TMT-S1-F001 | B40: TMT | C40: S1 | E40: EE1 End User (Browser) Process Memory Tampered | F40: Diagram 1 | G40: Registration/Login Credentials | H40: TMT/S1
A41: TMT-S1-F002 | B41: TMT | C41: S1 | E41: Cross Site Scripting | F41: Diagram 1 | G41: Registration/Login Credentials | H41: TMT/S1
A42: TMT-S1-F003 | B42: TMT | C42: S1 | E42: Elevation Using Impersonation | F42: Diagram 1 | G42: Registration/Login Credentials | H42: TMT/S1
A43: TMT-S1-F004 | B43: TMT | C43: S1 | E43: P1 Web Frontend Interface Process Memory Tampered | F43: Diagram 1 | G43: Credential Submission | H43: TMT/S1
A44: TMT-S1-F005 | B44: TMT | C44: S1 | E44: Elevation Using Impersonation | F44: Diagram 1 | G44: Credential Submission | H44: TMT/S1
A45: TMT-S1-F006 | B45: TMT | C45: S1 | E45: Spoofing of Destination Data Store DS1 Backend User Database | F45: Diagram 1 | G45: Credential Verification Request | H45: TMT/S1
A46: TMT-S1-F007 | B46: TMT | C46: S1 | D46: injection_verification | E46: Potential SQL Injection Vulnerability for DS1 Backend User Database | F46: Diagram 1 | G46: Credential Verification Request | H46: TMT/S1
A47: TMT-S1-F008 | B47: TMT | C47: S1 | D47: dos_service | E47: Potential Excessive Resource Consumption for P2 Authentication Server or DS1 Backend User Database | F47: Diagram 1 | G47: Credential Verification Request | H47: TMT/S1
A48: TMT-S1-F009 | B48: TMT | C48: S1 | E48: P2 Authentication Server Process Memory Tampered | F48: Diagram 1 | G48: Session Token Generation | H48: TMT/S1
A49: TMT-S1-F010 | B49: TMT | C49: S1 | E49: Elevation Using Impersonation | F49: Diagram 1 | G49: Session Token Generation | H49: TMT/S1
A50: TMT-S1-F011 | B50: TMT | C50: S1 | E50: P2 Authentication Server Process Memory Tampered | F50: Diagram 1 | G50: Authentication Result | H50: TMT/S1
A51: TMT-S1-F012 | B51: TMT | C51: S1 | E51: Cross Site Scripting | F51: Diagram 1 | G51: Authentication Result | H51: TMT/S1
A52: TMT-S1-F013 | B52: TMT | C52: S1 | E52: Elevation Using Impersonation | F52: Diagram 1 | G52: Authentication Result | H52: TMT/S1
A53: TMT-S1-F014 | B53: TMT | C53: S1 | E53: Spoofing of Source Data Store DS1 Backend User Database | F53: Diagram 1 | G53: Credential Verification Result | H53: TMT/S1
A54: TMT-S1-F015 | B54: TMT | C54: S1 | D54: mass_disclosure | E54: Weak Access Control for a Resource | F54: Diagram 1 | G54: Credential Verification Result | H54: TMT/S1
A55: TMT-S1-F016 | B55: TMT | C55: S1 | E55: P3 Session Management Module Process Memory Tampered | F55: Diagram 1 | G55: Session Token | H55: TMT/S1
A56: TMT-S1-F017 | B56: TMT | C56: S1 | D56: transit_token | E56: Cross Site Scripting | F56: Diagram 1 | G56: Session Token | H56: TMT/S1
A57: TMT-S1-F018 | B57: TMT | C57: S1 | E57: Elevation Using Impersonation | F57: Diagram 1 | G57: Session Token | H57: TMT/S1
A58: TMT-S1-F019 | B58: TMT | C58: S1 | E58: P1 Web Frontend Interface Process Memory Tampered | F58: Diagram 1 | G58: Authenticated Session Response | H58: TMT/S1
A59: TMT-S1-F020 | B59: TMT | C59: S1 | E59: Elevation Using Impersonation | F59: Diagram 1 | G59: Authenticated Session Response | H59: TMT/S1
A60: TMT-S1-F021 | B60: TMT | C60: S1 | E60: Elevation Using Impersonation | F60: Diagram 1 | G60: Chatbot Question | H60: TMT/S1
A61: TMT-S1-F022 | B61: TMT | C61: S1 | E61: EE1 End User (Browser) Process Memory Tampered | F61: Diagram 1 | G61: Chatbot Question | H61: TMT/S1
A62: TMT-S1-F023 | B62: TMT | C62: S1 | E62: Potential Process Crash or Stop for EE1 End User (Browser) | F62: Diagram 1 | G62: Chatbot Answer | H62: TMT/S1
A63: TMT-S1-F024 | B63: TMT | C63: S1 | E63: Data Flow Sniffing | F63: Diagram 1 | G63: Chatbot Answer | H63: TMT/S1
A64: TMT-S1-F025 | B64: TMT | C64: S1 | D64: repudiation | E64: Potential Data Repudiation by EE1 End User (Browser) | F64: Diagram 1 | G64: Chatbot Answer | H64: TMT/S1
A65: TMT-S1-F026 | B65: TMT | C65: S1 | E65: P4 AI Authentication Assistant Process Memory Tampered | F65: Diagram 1 | G65: Chatbot Answer | H65: TMT/S1
...

Sheet 04_MATCHING
A1: Semantic Matching Decisions (1,025 findings)
A2: OWASP-S1-F001 | B2: OWASP | C2: S1 | D2: =IFERROR(VLOOKUP($G2,'02_REFERENCE'!$A$2:$S$99,4,FALSE),"N/A") -> N/A | E2: =IFERROR(VLOOKUP($G2,'02_REFERENCE'!$A$2:$S$99,15,FALSE),"N/A") -> N/A | F2: =IFERROR(VLOOKUP($G2,'02_REFERENCE'!$A$2:$S$99,17,FALSE),"N/A") -> N/A | H2: False Positive | I2: FP | J2: M | K2: N | L2: No | N2: OWASP Automated Threat #9 (CAPTCHA defeat): the drawn architecture contains no CAPTCHA control; threat depends on absent functionality. | O2: captcha | P2: CAPTCHA defeat | Q2: EE1 End User | S2: Confirmed
A3: OWASP-S1-F002 | B3: OWASP | C3: S1 | D3: =IFERROR(VLOOKUP($G3,'02_REFERENCE'!$A$2:$S$99,4,FALSE),"N/A") -> Spoofing | E3: =IFERROR(VLOOKUP($G3,'02_REFERENCE'!$A$2:$S$99,15,FALSE),"N/A") -> High | F3: =IFERROR(VLOOKUP($G3,'02_REFERENCE'!$A$2:$S$99,17,FALSE),"N/A") -> No | G3: S1-RT-002 | H3: Primary TP | I3: TP | J3: H | K3: Y | L3: No | N3: Mechanism: replayed stolen credentials against login (OWASP Automated Threat #8) -> reference S1-RT-002. | O3: credential_stuffing | P3: Credential stuffing | Q3: EE1 End User | S3: Confirmed
A4: OWASP-S1-F003 | B4: OWASP | C4: S1 | D4: =IFERROR(VLOOKUP($G4,'02_REFERENCE'!$A$2:$S$99,4,FALSE),"N/A") -> N/A | E4: =IFERROR(VLOOKUP($G4,'02_REFERENCE'!$A$2:$S$99,15,FALSE),"N/A") -> N/A | F4: =IFERROR(VLOOKUP($G4,'02_REFERENCE'!$A$2:$S$99,17,FALSE),"N/A") -> N/A | H4: False Positive | I4: FP | J4: M | K4: N | L4: No | N4: Generic least-privilege hardening template (horizontal/lateral EoP after compromise); no reference threat specifies this mechanism for this element. | O4: excessive_db_scope | P4: Least privilege | Q4: P1 Web Frontend Interface | S4: Confirmed
A5: OWASP-S1-F004 | B5: OWASP | C5: S1 | D5: =IFERROR(VLOOKUP($G5,'02_REFERENCE'!$A$2:$S$99,4,FALSE),"N/A") -> N/A | E5: =IFERROR(VLOOKUP($G5,'02_REFERENCE'!$A$2:$S$99,15,FALSE),"N/A") -> N/A | F5: =IFERROR(VLOOKUP($G5,'02_REFERENCE'!$A$2:$S$99,17,FALSE),"N/A") -> N/A | H5: False Positive | I5: FP | J5: M | K5: N | L5: No | N5: Expedition (OWASP Automated Threat #6): generic automation/abuse-agility template; no single reference mechanism matches (brute force / stuffing are distinct specialist mechanisms). | O5: expedition | P5: Expedition | Q5: P1 Web Frontend Interface | S5: Confirmed
A6: OWASP-S1-F005 | B6: OWASP | C6: S1 | D6: =IFERROR(VLOOKUP($G6,'02_REFERENCE'!$A$2:$S$99,4,FALSE),"N/A") -> N/A | E6: =IFERROR(VLOOKUP($G6,'02_REFERENCE'!$A$2:$S$99,15,FALSE),"N/A") -> N/A | F6: =IFERROR(VLOOKUP($G6,'02_REFERENCE'!$A$2:$S$99,17,FALSE),"N/A") -> N/A | H6: False Positive | I6: FP | J6: M | K6: N | L6: No | N6: Vulnerability scanning (OWASP Automated Threat #14): reconnaissance; not a security-failure mechanism present in the baseline. | O6: recon | P6: Vulnerability scanning | Q6: P1 Web Frontend Interface | S6: Confirmed
A7: OWASP-S1-F006 | B7: OWASP | C7: S1 | D7: =IFERROR(VLOOKUP($G7,'02_REFERENCE'!$A$2:$S$99,4,FALSE),"N/A") -> Denial of Service | E7: =IFERROR(VLOOKUP($G7,'02_REFERENCE'!$A$2:$S$99,15,FALSE),"N/A") -> Medium | F7: =IFERROR(VLOOKUP($G7,'02_REFERENCE'!$A$2:$S$99,17,FALSE),"N/A") -> No | G7: S1-RT-028 | H7: Primary TP | I7: TP | J7: M | K7: Y | L7: No | N7: Resource-exhaustion template on the primary service path -> reference S1-RT-028. | O7: dos_service | P7: Denial of Service | Q7: P1 Web Frontend Interface | S7: Confirmed
A8: OWASP-S1-F007 | B8: OWASP | C8: S1 | D8: =IFERROR(VLOOKUP($G8,'02_REFERENCE'!$A$2:$S$99,4,FALSE),"N/A") -> N/A | E8: =IFERROR(VLOOKUP($G8,'02_REFERENCE'!$A$2:$S$99,15,FALSE),"N/A") -> N/A | F8: =IFERROR(VLOOKUP($G8,'02_REFERENCE'!$A$2:$S$99,17,FALSE),"N/A") -> N/A | H8: False Positive | I8: FP | J8: M | K8: N | L8: No | N8: Footprinting/Fingerprinting (OWASP Automated Threat #18/#4): reconnaissance; no reference mechanism. | O8: recon | P8: Footprinting | Q8: P1 Web Frontend Interface | S8: Confirmed
A9: OWASP-S1-F008 | B9: OWASP | C9: S1 | D9: =IFERROR(VLOOKUP($G9,'02_REFERENCE'!$A$2:$S$99,4,FALSE),"N/A") -> N/A | E9: =IFERROR(VLOOKUP($G9,'02_REFERENCE'!$A$2:$S$99,15,FALSE),"N/A") -> N/A | F9: =IFERROR(VLOOKUP($G9,'02_REFERENCE'!$A$2:$S$99,17,FALSE),"N/A") -> N/A | H9: False Positive | I9: FP | J9: M | K9: N | L9: No | N9: Generic least-privilege hardening template (horizontal/lateral EoP after compromise); no reference threat specifies this mechanism for this element. | O9: excessive_db_scope | P9: Least privilege | Q9: P2 Authentication Service | S9: Confirmed
A10: OWASP-S1-F009 | B10: OWASP | C10: S1 | D10: =IFERROR(VLOOKUP($G10,'02_REFERENCE'!$A$2:$S$99,4,FALSE),"N/A") -> N/A | E10: =IFERROR(VLOOKUP($G10,'02_REFERENCE'!$A$2:$S$99,15,FALSE),"N/A") -> N/A | F10: =IFERROR(VLOOKUP($G10,'02_REFERENCE'!$A$2:$S$99,17,FALSE),"N/A") -> N/A | H10: False Positive | I10: FP | J10: M | K10: N | L10: No | N10: Expedition (OWASP Automated Threat #6): generic automation/abuse-agility template; no single reference mechanism matches (brute force / stuffing are distinct specialist mechanisms). | O10: expedition | P10: Expedition | Q10: P2 Authentication Service | S10: Confirmed
A11: OWASP-S1-F010 | B11: OWASP | C11: S1 | D11: =IFERROR(VLOOKUP($G11,'02_REFERENCE'!$A$2:$S$99,4,FALSE),"N/A") -> N/A | E11: =IFERROR(VLOOKUP($G11,'02_REFERENCE'!$A$2:$S$99,15,FALSE),"N/A") -> N/A | F11: =IFERROR(VLOOKUP($G11,'02_REFERENCE'!$A$2:$S$99,17,FALSE),"N/A") -> N/A | H11: False Positive | I11: FP | J11: M | K11: N | L11: No | N11: Vulnerability scanning (OWASP Automated Threat #14): reconnaissance; not a security-failure mechanism present in the baseline. | O11: recon | P11: Vulnerability scanning | Q11: P2 Authentication Service | S11: Confirmed
A12: OWASP-S1-F011 | B12: OWASP | C12: S1 | D12: =IFERROR(VLOOKUP($G12,'02_REFERENCE'!$A$2:$S$99,4,FALSE),"N/A") -> Denial of Service | E12: =IFERROR(VLOOKUP($G12,'02_REFERENCE'!$A$2:$S$99,15,FALSE),"N/A") -> Medium | F12: =IFERROR(VLOOKUP($G12,'02_REFERENCE'!$A$2:$S$99,17,FALSE),"N/A") -> No | G12: S1-RT-028 | H12: Duplicate | I12: TP | J12: M | K12: N | L12: Yes | M12: OWASP-S1-F006 | N12: Resource-exhaustion template on the primary service path -> reference S1-RT-028. [Equivalence: restates OWASP-S1-F006 — one-to-one rule applied.] | O12: dos_service | P12: Denial of Service | Q12: P2 Authentication Service | S12: Confirmed
A13: OWASP-S1-F012 | B13: OWASP | C13: S1 | D13: =IFERROR(VLOOKUP($G13,'02_REFERENCE'!$A$2:$S$99,4,FALSE),"N/A") -> N/A | E13: =IFERROR(VLOOKUP($G13,'02_REFERENCE'!$A$2:$S$99,15,FALSE),"N/A") -> N/A | F13: =IFERROR(VLOOKUP($G13,'02_REFERENCE'!$A$2:$S$99,17,FALSE),"N/A") -> N/A | H13: False Positive | I13: FP | J13: M | K13: N | L13: No | N13: Footprinting/Fingerprinting (OWASP Automated Threat #18/#4): reconnaissance; no reference mechanism. | O13: recon | P13: Footprinting | Q13: P2 Authentication Service | S13: Confirmed
A14: OWASP-S1-F013 | B14: OWASP | C14: S1 | D14: =IFERROR(VLOOKUP($G14,'02_REFERENCE'!$A$2:$S$99,4,FALSE),"N/A") -> N/A | E14: =IFERROR(VLOOKUP($G14,'02_REFERENCE'!$A$2:$S$99,15,FALSE),"N/A") -> N/A | F14: =IFERROR(VLOOKUP($G14,'02_REFERENCE'!$A$2:$S$99,17,FALSE),"N/A") -> N/A | H14: False Positive | I14: FP | J14: M | K14: N | L14: No | N14: Generic least-privilege hardening template (horizontal/lateral EoP after compromise); no reference threat specifies this mechanism for this element. | O14: excessive_db_scope | P14: Least privilege | Q14: P3 Session Management Module | S14: Confirmed
A15: OWASP-S1-F014 | B15: OWASP | C15: S1 | D15: =IFERROR(VLOOKUP($G15,'02_REFERENCE'!$A$2:$S$99,4,FALSE),"N/A") -> N/A | E15: =IFERROR(VLOOKUP($G15,'02_REFERENCE'!$A$2:$S$99,15,FALSE),"N/A") -> N/A | F15: =IFERROR(VLOOKUP($G15,'02_REFERENCE'!$A$2:$S$99,17,FALSE),"N/A") -> N/A | H15: False Positive | I15: FP | J15: M | K15: N | L15: No | N15: Expedition (OWASP Automated Threat #6): generic automation/abuse-agility template; no single reference mechanism matches (brute force / stuffing are distinct specialist mechanisms). | O15: expedition | P15: Expedition | Q15: P3 Session Management Module | S15: Confirmed
A16: OWASP-S1-F015 | B16: OWASP | C16: S1 | D16: =IFERROR(VLOOKUP($G16,'02_REFERENCE'!$A$2:$S$99,4,FALSE),"N/A") -> N/A | E16: =IFERROR(VLOOKUP($G16,'02_REFERENCE'!$A$2:$S$99,15,FALSE),"N/A") -> N/A | F16: =IFERROR(VLOOKUP($G16,'02_REFERENCE'!$A$2:$S$99,17,FALSE),"N/A") -> N/A | H16: False Positive | I16: FP | J16: M | K16: N | L16: No | N16: Vulnerability scanning (OWASP Automated Threat #14): reconnaissance; not a security-failure mechanism present in the baseline. | O16: recon | P16: Vulnerability scanning | Q16: P3 Session Management Module | S16: Confirmed
A17: OWASP-S1-F016 | B17: OWASP | C17: S1 | D17: =IFERROR(VLOOKUP($G17,'02_REFERENCE'!$A$2:$S$99,4,FALSE),"N/A") -> Denial of Service | E17: =IFERROR(VLOOKUP($G17,'02_REFERENCE'!$A$2:$S$99,15,FALSE),"N/A") -> Medium | F17: =IFERROR(VLOOKUP($G17,'02_REFERENCE'!$A$2:$S$99,17,FALSE),"N/A") -> No | G17: S1-RT-028 | H17: Duplicate | I17: TP | J17: M | K17: N | L17: Yes | M17: OWASP-S1-F006 | N17: Resource-exhaustion template on the primary service path -> reference S1-RT-028. [Equivalence: restates OWASP-S1-F006 — one-to-one rule applied.] | O17: dos_service | P17: Denial of Service | Q17: P3 Session Management Module | S17: Confirmed
A18: OWASP-S1-F017 | B18: OWASP | C18: S1 | D18: =IFERROR(VLOOKUP($G18,'02_REFERENCE'!$A$2:$S$99,4,FALSE),"N/A") -> N/A | E18: =IFERROR(VLOOKUP($G18,'02_REFERENCE'!$A$2:$S$99,15,FALSE),"N/A") -> N/A | F18: =IFERROR(VLOOKUP($G18,'02_REFERENCE'!$A$2:$S$99,17,FALSE),"N/A") -> N/A | H18: False Positive | I18: FP | J18: M | K18: N | L18: No | N18: Footprinting/Fingerprinting (OWASP Automated Threat #18/#4): reconnaissance; no reference mechanism. | O18: recon | P18: Footprinting | Q18: P3 Session Management Module | S18: Confirmed
A19: OWASP-S1-F018 | B19: OWASP | C19: S1 | D19: =IFERROR(VLOOKUP($G19,'02_REFERENCE'!$A$2:$S$99,4,FALSE),"N/A") -> Spoofing | E19: =IFERROR(VLOOKUP($G19,'02_REFERENCE'!$A$2:$S$99,15,FALSE),"N/A") -> Critical | F19: =IFERROR(VLOOKUP($G19,'02_REFERENCE'!$A$2:$S$99,17,FALSE),"N/A") -> No | G19: S1-RT-014 | H19: Primary TP | I19: TP | J19: M | K19: Y | L19: No | N19: Weak transport on session-management flows exposes issued session tokens at the delivery crossing -> reference S1-RT-014. | O19: transit_token | P19: Vulnerable transport protocol | Q19: P3 Session Management Module | S19: Confirmed
A20: OWASP-S1-F019 | B20: OWASP | C20: S1 | D20: =IFERROR(VLOOKUP($G20,'02_REFERENCE'!$A$2:$S$99,4,FALSE),"N/A") -> N/A | E20: =IFERROR(VLOOKUP($G20,'02_REFERENCE'!$A$2:$S$99,15,FALSE),"N/A") -> N/A | F20: =IFERROR(VLOOKUP($G20,'02_REFERENCE'!$A$2:$S$99,17,FALSE),"N/A") -> N/A | H20: False Positive | I20: FP | J20: M | K20: N | L20: No | N20: Footprinting/Fingerprinting (OWASP Automated Threat #18/#4): reconnaissance; no reference mechanism. | O20: recon | P20: Fingerprinting | Q20: P3 Session Management Module | S20: Confirmed
A21: OWASP-S1-F020 | B21: OWASP | C21: S1 | D21: =IFERROR(VLOOKUP($G21,'02_REFERENCE'!$A$2:$S$99,4,FALSE),"N/A") -> Spoofing | E21: =IFERROR(VLOOKUP($G21,'02_REFERENCE'!$A$2:$S$99,15,FALSE),"N/A") -> Critical | F21: =IFERROR(VLOOKUP($G21,'02_REFERENCE'!$A$2:$S$99,17,FALSE),"N/A") -> No | G21: S1-RT-014 | H21: Duplicate | I21: TP | J21: M | K21: N | L21: Yes | M21: OWASP-S1-F018 | N21: Weak transport on session-management flows exposes issued session tokens at the delivery crossing -> reference S1-RT-014. [Equivalence: restates OWASP-S1-F018 — one-to-one rule applied.] | O21: transit_token | P21: Vulnerable transport protocol | Q21: P3 Session Management Module | S21: Confirmed
A22: OWASP-S1-F021 | B22: OWASP | C22: S1 | D22: =IFERROR(VLOOKUP($G22,'02_REFERENCE'!$A$2:$S$99,4,FALSE),"N/A") -> Spoofing | E22: =IFERROR(VLOOKUP($G22,'02_REFERENCE'!$A$2:$S$99,15,FALSE),"N/A") -> Critical | F22: =IFERROR(VLOOKUP($G22,'02_REFERENCE'!$A$2:$S$99,17,FALSE),"N/A") -> No | G22: S1-RT-014 | H22: Duplicate | I22: TP | J22: M | K22: N | L22: Yes | M22: OWASP-S1-F018 | N22: Weak transport on session-management flows exposes issued session tokens at the delivery crossing -> reference S1-RT-014. [Equivalence: restates OWASP-S1-F018 — one-to-one rule applied.] | O22: transit_token | P22: Vulnerable transport protocol | Q22: P3 Session Management Module | S22: Confirmed
A23: OWASP-S1-F022 | B23: OWASP | C23: S1 | D23: =IFERROR(VLOOKUP($G23,'02_REFERENCE'!$A$2:$S$99,4,FALSE),"N/A") -> Spoofing | E23: =IFERROR(VLOOKUP($G23,'02_REFERENCE'!$A$2:$S$99,15,FALSE),"N/A") -> Critical | F23: =IFERROR(VLOOKUP($G23,'02_REFERENCE'!$A$2:$S$99,17,FALSE),"N/A") -> No | G23: S1-RT-014 | H23: Duplicate | I23: TP | J23: M | K23: N | L23: Yes | M23: OWASP-S1-F018 | N23: Weak transport on session-management flows exposes issued session tokens at the delivery crossing -> reference S1-RT-014. [Equivalence: restates OWASP-S1-F018 — one-to-one rule applied.] | O23: transit_token | P23: Vulnerable transport protocol | Q23: P3 Session Management Module | S23: Confirmed
A24: OWASP-S1-F023 | B24: OWASP | C24: S1 | D24: =IFERROR(VLOOKUP($G24,'02_REFERENCE'!$A$2:$S$99,4,FALSE),"N/A") -> N/A | E24: =IFERROR(VLOOKUP($G24,'02_REFERENCE'!$A$2:$S$99,15,FALSE),"N/A") -> N/A | F24: =IFERROR(VLOOKUP($G24,'02_REFERENCE'!$A$2:$S$99,17,FALSE),"N/A") -> N/A | H24: False Positive | I24: FP | J24: M | K24: N | L24: No | N24: Footprinting/Fingerprinting (OWASP Automated Threat #18/#4): reconnaissance; no reference mechanism. | O24: recon | P24: Fingerprinting | Q24: P3 Session Management Module | S24: Confirmed
A25: OWASP-S1-F024 | B25: OWASP | C25: S1 | D25: =IFERROR(VLOOKUP($G25,'02_REFERENCE'!$A$2:$S$99,4,FALSE),"N/A") -> N/A | E25: =IFERROR(VLOOKUP($G25,'02_REFERENCE'!$A$2:$S$99,15,FALSE),"N/A") -> N/A | F25: =IFERROR(VLOOKUP($G25,'02_REFERENCE'!$A$2:$S$99,17,FALSE),"N/A") -> N/A | H25: False Positive | I25: FP | J25: M | K25: N | L25: No | N25: Expedition (OWASP Automated Threat #6): generic automation/abuse-agility template; no single reference mechanism matches (brute force / stuffing are distinct specialist mechanisms). | O25: expedition | P25: Expedition | Q25: P4 AI chatbot Component | S25: Confirmed
A26: OWASP-S1-F025 | B26: OWASP | C26: S1 | D26: =IFERROR(VLOOKUP($G26,'02_REFERENCE'!$A$2:$S$99,4,FALSE),"N/A") -> N/A | E26: =IFERROR(VLOOKUP($G26,'02_REFERENCE'!$A$2:$S$99,15,FALSE),"N/A") -> N/A | F26: =IFERROR(VLOOKUP($G26,'02_REFERENCE'!$A$2:$S$99,17,FALSE),"N/A") -> N/A | H26: False Positive | I26: FP | J26: M | K26: N | L26: No | N26: Vulnerability scanning (OWASP Automated Threat #14): reconnaissance; not a security-failure mechanism present in the baseline. | O26: recon | P26: Vulnerability scanning | Q26: P4 AI chatbot Component | S26: Confirmed
A27: OWASP-S1-F026 | B27: OWASP | C27: S1 | D27: =IFERROR(VLOOKUP($G27,'02_REFERENCE'!$A$2:$S$99,4,FALSE),"N/A") -> Denial of Service | E27: =IFERROR(VLOOKUP($G27,'02_REFERENCE'!$A$2:$S$99,15,FALSE),"N/A") -> Medium | F27: =IFERROR(VLOOKUP($G27,'02_REFERENCE'!$A$2:$S$99,17,FALSE),"N/A") -> Yes | G27: S1-RT-030 | H27: Primary TP | I27: TP | J27: M | K27: Y | L27: No | N27: Resource-exhaustion template on the LLM pipeline component -> reference S1-RT-030 (unbounded LLM pipeline consumption). | O27: llm_consumption | P27: Denial of Service | Q27: P4 AI chatbot Component | S27: Confirmed
A28: OWASP-S1-F027 | B28: OWASP | C28: S1 | D28: =IFERROR(VLOOKUP($G28,'02_REFERENCE'!$A$2:$S$99,4,FALSE),"N/A") -> N/A | E28: =IFERROR(VLOOKUP($G28,'02_REFERENCE'!$A$2:$S$99,15,FALSE),"N/A") -> N/A | F28: =IFERROR(VLOOKUP($G28,'02_REFERENCE'!$A$2:$S$99,17,FALSE),"N/A") -> N/A | H28: False Positive | I28: FP | J28: M | K28: N | L28: No | N28: Expedition (OWASP Automated Threat #6): generic automation/abuse-agility template; no single reference mechanism matches (brute force / stuffing are distinct specialist mechanisms). | O28: expedition | P28: Expedition | Q28: P5 LLM Integration Service | S28: Confirmed
A29: OWASP-S1-F028 | B29: OWASP | C29: S1 | D29: =IFERROR(VLOOKUP($G29,'02_REFERENCE'!$A$2:$S$99,4,FALSE),"N/A") -> N/A | E29: =IFERROR(VLOOKUP($G29,'02_REFERENCE'!$A$2:$S$99,15,FALSE),"N/A") -> N/A | F29: =IFERROR(VLOOKUP($G29,'02_REFERENCE'!$A$2:$S$99,17,FALSE),"N/A") -> N/A | H29: False Positive | I29: FP | J29: M | K29: N | L29: No | N29: Vulnerability scanning (OWASP Automated Threat #14): reconnaissance; not a security-failure mechanism present in the baseline. | O29: recon | P29: Vulnerability scanning | Q29: P5 LLM Integration Service | S29: Confirmed
A30: OWASP-S1-F029 | B30: OWASP | C30: S1 | D30: =IFERROR(VLOOKUP($G30,'02_REFERENCE'!$A$2:$S$99,4,FALSE),"N/A") -> Denial of Service | E30: =IFERROR(VLOOKUP($G30,'02_REFERENCE'!$A$2:$S$99,15,FALSE),"N/A") -> Medium | F30: =IFERROR(VLOOKUP($G30,'02_REFERENCE'!$A$2:$S$99,17,FALSE),"N/A") -> Yes | G30: S1-RT-030 | H30: Duplicate | I30: TP | J30: M | K30: N | L30: Yes | M30: OWASP-S1-F026 | N30: Resource-exhaustion template on the LLM pipeline component -> reference S1-RT-030 (unbounded LLM pipeline consumption). [Equivalence: restates OWASP-S1-F026 — one-to-one rule applied.] | O30: llm_consumption | P30: Denial of Service | Q30: P5 LLM Integration Service | S30: Confirmed
A31: OWASP-S1-F030 | B31: OWASP | C31: S1 | D31: =IFERROR(VLOOKUP($G31,'02_REFERENCE'!$A$2:$S$99,4,FALSE),"N/A") -> Information Disclosure | E31: =IFERROR(VLOOKUP($G31,'02_REFERENCE'!$A$2:$S$99,15,FALSE),"N/A") -> Critical | F31: =IFERROR(VLOOKUP($G31,'02_REFERENCE'!$A$2:$S$99,17,FALSE),"N/A") -> No | G31: S1-RT-018 | H31: Primary TP | I31: TP | J31: M | K31: Y | L31: No | N31: Scraping (OWASP Automated Threat #11) on the user-data-store element: automated bulk collection of stored user data corresponds to the mass-disclosure mechanism -> reference S1-RT-018. | O31: mass_disclosure | P31: Scraping | Q31: DS1 User Database | S31: Confirmed
A32: OWASP-S1-F031 | B32: OWASP | C32: S1 | D32: =IFERROR(VLOOKUP($G32,'02_REFERENCE'!$A$2:$S$99,4,FALSE),"N/A") -> N/A | E32: =IFERROR(VLOOKUP($G32,'02_REFERENCE'!$A$2:$S$99,15,FALSE),"N/A") -> N/A | F32: =IFERROR(VLOOKUP($G32,'02_REFERENCE'!$A$2:$S$99,17,FALSE),"N/A") -> N/A | H32: False Positive | I32: FP | J32: M | K32: N | L32: No | N32: Skewing (OWASP Automated Threat #16): metric-frequency gaming; no matching reference mechanism. | O32: skew_spam | P32: Skewing | Q32: DS1 User Database | S32: Confirmed
A33: OWASP-S1-F032 | B33: OWASP | C33: S1 | D33: =IFERROR(VLOOKUP($G33,'02_REFERENCE'!$A$2:$S$99,4,FALSE),"N/A") -> N/A | E33: =IFERROR(VLOOKUP($G33,'02_REFERENCE'!$A$2:$S$99,15,FALSE),"N/A") -> N/A | F33: =IFERROR(VLOOKUP($G33,'02_REFERENCE'!$A$2:$S$99,17,FALSE),"N/A") -> N/A | H33: False Positive | I33: FP | J33: M | K33: N | L33: No | N33: Storing malicious content (OWASP Automated Threat #17) on an element without a matching malicious-content reference. | O33: skew_spam | P33: Spamming | Q33: DS1 User Database | S33: Confirmed
A34: OWASP-S1-F033 | B34: OWASP | C34: S1 | D34: =IFERROR(VLOOKUP($G34,'02_REFERENCE'!$A$2:$S$99,4,FALSE),"N/A") -> N/A | E34: =IFERROR(VLOOKUP($G34,'02_REFERENCE'!$A$2:$S$99,15,FALSE),"N/A") -> N/A | F34: =IFERROR(VLOOKUP($G34,'02_REFERENCE'!$A$2:$S$99,17,FALSE),"N/A") -> N/A | H34: False Positive | I34: FP | J34: M | K34: N | L34: No | N34: Scraping (OWASP Automated Threat #11) on a non-user-store element: collection of accessible application output, not the store-layer bulk-read mechanism of the mass-disclosure reference. | O34: mass_disclosure | P34: Scraping | Q34: DS2 Session Storage | S34: Confirmed
A35: OWASP-S1-F034 | B35: OWASP | C35: S1 | D35: =IFERROR(VLOOKUP($G35,'02_REFERENCE'!$A$2:$S$99,4,FALSE),"N/A") -> N/A | E35: =IFERROR(VLOOKUP($G35,'02_REFERENCE'!$A$2:$S$99,15,FALSE),"N/A") -> N/A | F35: =IFERROR(VLOOKUP($G35,'02_REFERENCE'!$A$2:$S$99,17,FALSE),"N/A") -> N/A | H35: False Positive | I35: FP | J35: M | K35: N | L35: No | N35: Skewing (OWASP Automated Threat #16): metric-frequency gaming; no matching reference mechanism. | O35: skew_spam | P35: Skewing | Q35: DS2 Session Storage | S35: Confirmed
A36: OWASP-S1-F035 | B36: OWASP | C36: S1 | D36: =IFERROR(VLOOKUP($G36,'02_REFERENCE'!$A$2:$S$99,4,FALSE),"N/A") -> N/A | E36: =IFERROR(VLOOKUP($G36,'02_REFERENCE'!$A$2:$S$99,15,FALSE),"N/A") -> N/A | F36: =IFERROR(VLOOKUP($G36,'02_REFERENCE'!$A$2:$S$99,17,FALSE),"N/A") -> N/A | H36: False Positive | I36: FP | J36: M | K36: N | L36: No | N36: Storing malicious content (OWASP Automated Threat #17) on an element without a matching malicious-content reference. | O36: skew_spam | P36: Spamming | Q36: DS2 Session Storage | S36: Confirmed
